Workbook

Sheet Sheet1
D1: UNITY UNIVERSITY ADAMA SPECIAL CAMPUS
D2: BUADF/R/10FIRST 2017(2010 E.C) ATTENDANCE FORM
B3: COURSE TITLE:MATHS FOR MANAGEMENT | F3: COURSE NO:MGMT221-----INST--Z
G4: DATE
A5: NO. | B5: NAME | C5: M.NAME | D5: COURSE ADDED | E5: ID.NO
A6: 1 | B6: Alem | C6: Kefylew
A7: 2 | B7: Abenet | C7: Fikadu | E7: 00929/10
A8: 3 | B8: Abenezer | C8: Tsegaye | E8: 00827/10
A9: 4 | B9: Alham | C9: Farid | E9: 00685/10
A10: 5 | B10: Azina | C10: Mulusew | E10: 009331/10
A11: 6 | B11: Bereket | C11: Birahenu
A12: 7 | B12: Betel | C12: Negatu | E12: 00901/10
A13: 8 | B13: Betelhem | C13: Asnake | E13: 00581/10
A14: 9 | B14: Bethelhem | C14: Demissie | E14: 00828/10
A15: 10 | B15: Betelhem | C15: Kindu | E15: 00735/10
A16: 11 | B16: Biftu | C16: Kebede | E16: 00776/10
A17: 12 | B17: Biniyam | C17: Engidaye | E17: 00590/10
A18: 13 | B18: Biniyam | C18: Bayisa | E18: 00925/10
A19: 14 | B19: Biniyam | C19: G/igizabher
A20: 15 | B20: Biruk | C20: Afework | E20: 00926/10
A21: 16 | B21: Besufikad | C21: Tadele | E21: 00224/10
A22: 17 | B22: Dagim | C22: Girma | E22: 00928/10
A23: 18 | B23: Ephrem | C23: Eyasu | E23: 00718/10
A24: 19 | B24: Fison | C24: Mekonnen | E24: 00598/10
A25: 20 | B25: Frehiwot | C25: Demissie | E25: 00757/10
A26: 21 | B26: Hizekael | C26: Shimeles | E26: 00830/10
A27: 22 | B27: Hosana | C27: Gizaw | E27: 00832/10
A28: 23 | B28: Henok | C28: Mekoya | E28: 00853/10
A29: 24 | B29: Kaleab | C29: Awoke | E29: 00927/10
A30: 25 | B30: Mesoud | C30: Merzuk | E30: 00677/10
A31: 26 | B31: Mihret | C31: Gidey | E31: 00945/10
... A33: 28 | B33: Meklit | C33: Girma | E33: 00621/10
A34: 29 | B34: Salahdin | C34: Abu
A35: 30 | B35: Selamawit | C35: Assefa | E35: 00605/10
A36: 31 | B36: Sosina | C36: Tamirat | E36: 00902/10
A37: 32 | B37: Tesfalew | C37: Solomon
A38: 33 | B38: Tewodros | C38: Tesfaye | E38: 00831/10
A39: 34 | B39: Tewoflos | C39: Tebebe | E39: 00681/10
A41: 1 | B41: Abdulkerim | C41: Nesro | E41: 01016/10
A42: 2 | B42: Abel | C42: Ayele | E42: 01008/10
...

Sheet ATT-MGMT-BUAD-SPECILA CLASS-11
A1: BUAD/R/10
A2: UNITY UNIVERSITY ADAMA SPECIAL CAMPUS
A3: MGMT/BUAD/SPECIAL CLASS/11 1ST SEM. 2019/20 (2012 E.C) ATTENDANCE FORM
A5: COURSE TITLE: Priciple of accounting I | J5: COURSE NO: Acfn 201 | R5: INSTRUCTOR:
A6: NO. | B6: STUDENTS NAME | C6: SEX | D6: ID.NO
A7: 1 | B7: Abenezer Tsegaye Tasew | C7: M | D7: 00827/10
A8: 2 | B8: Ahlam Farid Abdullah | D8: 00685/10
A9: 3 | B9: Amir Mohammednur Abdure | C9: M | D9: 00893/10
A10: 4 | B10: Azinas Mulusew | C10: M | D10: 00931/10
A11: 5 | B11: Bamlak Lulseged Biru | C11: M | D11: 00990/10
A12: 6 | B12: Bekalu Endale Dejene | C12: M | D12: 01078/10
A13: 7 | B13: Betel Negatu Abera | C13: F | D13: 00901/10
A14: 8 | B14: Betelhem Asnake Ademe | C14: F | D14: 00581/10
A15: 9 | B15: Betelhem Demisew Truneh | C15: F | D15: 00828/10
A16: 10 | B16: Betelhem Kindu | C16: F | D16: 00735/10
A17: 11 | B17: Biftu Kebede Abdi | C17: F | D17: 00776/10
A18: 12 | B18: Biniyam Engdaye Baye | C18: M | D18: 00590/10
A19: 13 | B19: Dagim Daniel Worku | C19: M | D19: 01077/10
A20: 14 | B20: Dagim Girma | C20: M | D20: 00928/10
... A24: 18 | B24: Filagot Tesfaye Hile | C24: F | D24: 01462/11
A25: 19 | B25: Firaol Teshome Melka | D25: 00989/10
A26: 20 | B26: Fison Mekonnen Getachew | C26: F | D26: 00598/10
A27: 21 | B27: Frehiwot Demis | C27: F | D27: 00757/10
A28: 22 | B28: Habtamu G/egziabher Redai | C28: M | D28: 01002/10
A29: 23 | B29: Hana Alemayehu Beyecha | C29: F | D29: 00894/10
A30: 24 | B30: Hizkel Shimels Habte | C30: M | D30: 00830/10
A31: 25 | B31: Kaleab Awoke Kebede | C31: M | D31: 00927/10
A32: 26 | B32: Kaleab Fantahun Belay | C32: M | D32: 01021/10
A33: 27 | B33: Kewser Mohammed Seid | C33: F | D33: 01013/10
A34: 28 | B34: Meklit Girma Eshetu | C34: F | D34: 00621/10
A35: 29 | B35: Mesoud Merzuk | C35: M | D35: 00677/10
A36: 30 | B36: Mihret Genene Wolde | C36: F | D36: 00680/10
A37: 31 | B37: Mihret Gidey Abrham | C37: F | D37: 00945//0
... A47: 41 | B47: Yosef Kefyalew Gizaw | C47: M | D47: 01063/10
A48: 42
A49: 43
A50: 44
A51: 45
A52: 46
A53: ADD STUDENTS
...

Sheet Chart1

Sheet BUAD-R-09
B1: UNITY UNIVERSITY
B2: ADAMA SPECIAL CAMPUS
B3: OFFICE OF REGISTRAR
B4: GRADE SUBMISION FORM
B5: YEAR II SEM II /2018 | G5: =B5 -> YEAR II SEM II /2018
B6: COURSE TITLE: | G6: COURSE TITLE:
B7: MANAGEMENT INFORMATION SYSTEM | G7: =B7 -> MANAGEMENT INFORMATION SYSTEM
B8: COURSENO.MGMT311 | G8: =B8 -> COURSENO.MGMT311
B9: SECTION:BUAD/R/09_1 | G9: =B9 -> SECTION:BUAD/R/09_1
A10: S.N | B10: STUDENTS NAME | C10: ID.NO | D10: GRADE | H10: ID.NO | I10: GRADE
A11: 1 | B11: BESUFEKAD TADELE | C11: 00224/09 | H11: =C11 -> 00224/09
A12: 2 | B12: BETELHEM HAGOS | C12: 00225/09 | E12: Grade Summary | H12: =C12 -> 00225/09
A13: 3 | B13: FETIYA NASIR | C13: 00249/09 | E13: A+'S------ | H13: =C13 -> 00249/09
A14: 4 | B14: FETIYA WEZIR | C14: 00231/09 | E14: A'S | H14: =C14 -> 00231/09
A15: 5 | B15: HAMDI KADIRO | C15: 45599/09 | E15: B+'S----- | H15: =C15 -> 45599/09
A16: 6 | B16: HAMZA HABIBA | C16: 00227/09 | E16: B'S------- | H16: =C16 -> 00227/09
A17: 7 | B17: HANAN ABDO | C17: 00230/09 | E17: C+'S----- | H17: =C17 -> 00230/09
A18: 8 | B18: LEYILA FERIJA | C18: 00226/09 | E18: C'S------ | H18: =C18 -> 00226/09
A19: 9 | B19: LIDIYA AFEWORK | C19: 00362/09 | E19: D'S------ | H19: =C19 -> 00362/09
A20: 10 | B20: MAHLET DEREJE | C20: 00239/09 | E20: NG'S----- | H20: =C20 -> 00239/09
A21: 11 | B21: REKIK TILAHUN | C21: 00242/09 | E21: I'S-------- | H21: =C21 -> 00242/09
A22: 12 | B22: SAMIRA NASIRA | C22: 00220/09 | E22: TOT----- | H22: =C22 -> 00220/09
A23: 13 | B23: TEDI FIKRE | C23: 00324/09 | H23: =C23 -> 00324/09
A24: 14 | B24: TESFALEW SOLOMON | C24: 00413/10 | H24: =C24 -> 00413/10
A25: 15 | B25: YEMARISHET GIRMA | C25: 00229/09 | H25: =C25 -> 00229/09
A26: 16 | B26: YOKABED GOBENA | C26: 00241/09 | H26: =C26 -> 00241/09
B27: ADD STUDENTS | G27: ADD STUDENTS
A28: 1 | B28: HANA MEKONEN | C28: 00287/09 | H28: 00287/09
A29: 2 | B29: RUKIA YIMAM | C29: 00234/09 | H29: 00234/09
A30: 3
A31: 4
A32: 5
A33: 6
A34: 7
B43: UNITY UNIVERSITY
B44: ADAMA SPECIAL CAMPUS
B45: OFFICE OF REGISTRAR
B46: GRADE SUBMISION FORM
B47: YEAR II SEM II /2018 | G47: =B47 -> YEAR II SEM II /2018
B48: COURSE TITLE: | G48: COURSE TITLE:
...

Sheet MGMT-R-09
B1: UNITY UNIVERSITY
B2: ADAMA SPECIAL CAMPUS
B3: OFFICE OF REGISTRAR
B4: GRADE SUBMISION FORM
B5: YEAR II SEM II /2018 | G5: =B5 -> YEAR II SEM II /2018 | H5: =B5 -> YEAR II SEM II /2018
B6: COURSE TITLE: | G6: COURSE TITLE: | H6: =B6 -> COURSE TITLE:
B7: MANAGEMENT INFORMATION SYSTEM | G7: =B7 -> MANAGEMENT INFORMATION SYSTEM | H7: =B7 -> MANAGEMENT INFORMATION SYSTEM
B8: COURSENO.MGMT311 | G8: =B8 -> COURSENO.MGMT311
B9: SECTION:MGMT/R/09_1 | G9: =B9 -> SECTION:MGMT/R/09_1
A10: S.N | B10: STUDENTS NAME | C10: ID.NO | D10: GRADE | H10: ID.NO | I10: GRADE
A11: 1 | B11: ABDRHMAN SADIK | C11: 00319/09 | H11: =C11 -> 00319/09
A12: 2 | B12: ABENZER AYELE | C12: 00305/09 | E12: Grade Summary | H12: =C12 -> 00305/09
A13: 3 | B13: ADDISHIWOT ABEBE | C13: 00276/09 | E13: A+'S------ | H13: =C13 -> 00276/09
A14: 4 | B14: AYALNESH MITIKU | C14: 00285/09 | E14: A'S | H14: =C14 -> 00285/09
A15: 5 | B15: FASIKA MEASHO | C15: 00286/09 | E15: B+'S----- | H15: =C15 -> 00286/09
A16: 6 | B16: FEBEN DANIEL | C16: 00277/09 | E16: B'S------- | H16: =C16 -> 00277/09
A17: 7 | B17: FEVEN FELEKE | C17: 00283/09 | E17: C+'S----- | H17: =C17 -> 00283/09
A18: 8 | B18: GELETA BATI | C18: 00280/09 | E18: C'S------ | H18: =C18 -> 00280/09
A19: 9 | B19: HUNDUMA GUTETA | C19: 00275/09 | E19: D'S------ | H19: =C19 -> 00275/09
A20: 10 | B20: MENUR BEDRU | C20: 00272/09 | E20: NG'S----- | H20: =C20 -> 00272/09
A21: 11 | B21: MIKIYAS DESALEGN | C21: 00274/09 | E21: I'S-------- | H21: =C21 -> 00274/09
A22: 12 | B22: SELAMAWIT ERMIAS | C22: 00036/09 | E22: TOT----- | H22: =C22 -> 00036/09
A23: 13 | B23: SELAMAWIT TEMIS | C23: 00229/09 | H23: =C23 -> 00229/09
A24: 14 | B24: TIGIST TEKOLA | C24: 00282/09 | H24: =C24 -> 00282/09
A25: 15 | B25: WOYINISHET GEBEYEHU | C25: 00390/09 | H25: =C25 -> 00390/09
A26: 16 | B26: YESUF TESEMA | C26: 00351/09 | H26: =C26 -> 00351/09
B27: ADD STUDENTS | G27: ADD STUDENTS
A28: 1 | B28: ABEL NIGUSE | C28: 00010/09 | H28: =C28 -> 00010/09
A29: 2 | B29: EBRAHIM TAJUDIN | C29: 00398/10 | H29: =C29 -> 00398/10
A30: 3 | B30: FOZIA REDWAN | C30: 00443/09 | H30: =C30 -> 00443/09
A31: 4 | B31: HANIMA ENDRIS | C31: 00004/09 | H31: =C31 -> 00004/09
A32: 5 | B32: KALID SHEMSU | C32: 00326/09 | H32: =C32 -> 00326/09
A33: 6 | B33: KEDIRIYA ALEMAR | C33: 00424/09 | H33: =C33 -> 00424/09
A34: 7 | B34: MOHAMMED ALI | C34: 00104/09 | H34: =C34 -> 00104/09
A35: 8 | B35: NATINAEL SOLOMON | C35: 00307/09 | H35: =C35 -> 00307/09
A36: 9 | B36: ZEYIDA ETALA | C36: 00386/09 | H36: =C36 -> 00386/09
A37: 10
A38: 11
A39: 12
A40: 13
...

Sheet MRKT-R-09
B1: UNITY UNIVERSITY
B2: ADAMA SPECIAL CAMPUS
B3: OFFICE OF REGISTRAR
B4: GRADE SUBMISION FORM
B5: YEAR II SEM II /2018 | G5: =B5 -> YEAR II SEM II /2018
B6: COURSE TITLE: | G6: COURSE TITLE:
B7: MARKETING RESEARCH | G7: =B7 -> MARKETING RESEARCH
B8: COURSENO.MRKT421 | G8: =B8 -> COURSENO.MRKT421
B9: SECTION:MRKT/R/09_ | G9: =B9 -> SECTION:MRKT/R/09_
A10: S.N | B10: STUDENTS NAME | C10: ID.NO | D10: GRADE | H10: ID.NO | I10: GRADE
A11: 1 | B11: ALULA TSEGAYE | C11: 00261/09 | H11: =C11 -> 00261/09
A12: 2 | B12: BARSABET GENANAW | C12: 00264/09 | E12: Grade Summary | H12: =C12 -> 00264/09
A13: 3 | B13: BIRUK TOLOSA | C13: 00365/09 | E13: A+'S------ | H13: =C13 -> 00365/09
A14: 4 | B14: BIRUKTAWIT DADI | C14: 00246/09 | E14: A'S | H14: =C14 -> 00246/09
A15: 5 | B15: BEZAWIT KASAYE | C15: 00903/09 | E15: B+'S----- | H15: =C15 -> 00903/09
A16: 6 | B16: CHERNET TADELE | C16: 00001/08 | E16: B'S------- | H16: =C16 -> 00001/08
A17: 7 | B17: DAGMAWIT ASEBE | C17: 00244/09 | E17: C+'S----- | H17: =C17 -> 00244/09
A18: 8 | B18: EDEN SOLOMON | C18: 00400/09 | E18: C'S------ | H18: =C18 -> 00400/09
A19: 9 | B19: FERHIWOT TESFAYE | C19: 00145/09 | E19: D'S------ | H19: =C19 -> 00145/09
A20: 10 | B20: HANA GETACHEW | C20: 00401/09 | E20: NG'S----- | H20: =C20 -> 00401/09
A21: 11 | B21: HANAN KIYAR | C21: 00414/09 | E21: I'S-------- | H21: =C21 -> 00414/09
A22: 12 | B22: HANNY ABEBA | C22: 00258/09 | E22: TOT----- | H22: =C22 -> 00258/09
A23: 13 | B23: HAWI MERGIA | C23: 00254/09 | H23: =C23 -> 00254/09
A24: 14 | B24: HEWAN SOLOMON | C24: 00262/09 | H24: =C24 -> 00262/09
A25: 15 | B25: HEZEDIN MIFTA | C25: 00426/09 | H25: =C25 -> 00426/09
A26: 16 | B26: KALEAB GETACHEW | C26: 00265/09 | H26: =C26 -> 00265/09
A27: 17 | B27: MAHLET GEMECHU | C27: 00247/09 | H27: =C27 -> 00247/09
A28: 18 | B28: MASRESHA TEMSGEN | C28: 00263/09 | H28: =C28 -> 00263/09
A29: 19 | B29: MELAT ABDISA | C29: 25389/09 | H29: =C29 -> 25389/09
A30: 20 | B30: MERON G/HIWOT | C30: 00259/10 | H30: =C30 -> 00259/10
A31: 21 | B31: MEZERDIN MIFTA | C31: 00426/09 | H31: =C31 -> 00426/09
A32: 22 | B32: MIHRET TADELE | C32: 00256/09 | H32: =C32 -> 00256/09
A33: 23 | B33: NITSUHBIR GIRMA | C33: 00266/09 | H33: =C33 -> 00266/09
A34: 24 | B34: REDIET GASHAW | C34: 00095/09 | H34: =C34 -> 00095/09
... A37: 27 | B37: YISAK GIRMA | C37: 00257/09 | H37: =C37 -> 00257/09
A38: 6
A39: 1 | B39: AYINALEM MERSHA | C39: 000423/09 | H39: =C39 -> 000423/09
A40: 2 | B40: BILAL REDWAN | C40: 000364/09 | H40: =C40 -> 000364/09
A41: 3 | B41: FIREZER TSEGA | C41: 00260/09 | H41: =C41 -> 00260/09
A42: 4 | B42: NASIRE FEREJA | C42: 00251/09 | H42: =C42 -> 00251/09
...

Sheet ATT-BUAD-MRKT-MGMT-R-08
C1: UNITY UNIVERSITY ADAMA SPECIAL CAMPUS
C2: BUAD/08SECOND/SEM 2018 ATTENDENCE FORM
B3: COURSE TITLE:BUSINESS ETHICS AND LEADERSHIP
A4: NO. | B4: NAME | C4: ID.NO
A5: 1 | B5: ABERAR AMDELA | C5: 45488/08
A6: 2 | B6: BETELHEM ASHENAFI | C6: 45276/08
A7: 3 | B7: DANIEL KIFLE | C7: 45480/08
A8: 4 | B8: ELIAS FIKADU | C8: 00012/08
A9: 5 | B9: FAIZA MOHAMMED | C9: 45624/08
A10: 6 | B10: FIKIRU SIME | C10: 45504/08
A11: 7 | B11: FIRAOL ABERHAM | C11: 45460/09
A12: 8 | B12: HANA DESALEGN | C12: 45511/08
A13: 9 | B13: HANAN SANI | C13: 45520/08
A14: 10 | B14: HAWI MOHAMMED | C14: 45459/08
A15: 11 | B15: HELDANA GEBRU | C15: 45223/08
A16: 12 | B16: HUSINIYA KEDIR | C16: 45312/08
... A24: 20 | B24: WOINSHET AMSALU | C24: 45502/08
C25: ADD STUDENTS
A26: 1 | B26: BANDAMLAK ASSEFA | C26: 201/02
A27: 2 | B27: NOBEL ASSEFA | C27: 45578/08
A28: 3 | B28: ASFAWESEN MELESE | C28: 45560/08
A29: 4
A30: 5
A31: 6
A32: 7
A33: 8
A34: 9
A35: 10
C36: UNITY UNIVERSITY ADAMA SPECIAL CAMPUS
C37: BUAD/09 SECOND SEM 2018ATTENDENCE FORM
B39: COURSE TITLE:STRATEGIC MANAGEMENT
A40: NO. | B40: NAME | C40: ID.NO
A41: 1 | B41: ABERAR AMDELA | C41: 45488/08
A42: 2 | B42: BETELHEM ASHENAFI | C42: 45276/08
A43: 3 | B43: DANIEL KIFLE | C43: 45480/08
A44: 4 | B44: ELIAS FIKADU | C44: 00012/08
A45: 5 | B45: FAIZA MOHAMMED | C45: 45624/08
A46: 6 | B46: FIKIRU SIME | C46: 45504/08
A47: 7 | B47: FIRAOL ABERHAM | C47: 45460/09
A48: 8 | B48: HANA DESALEGN | C48: 45511/08
...

Sheet -BUAD-MRKT-MGMT-EX-08
C6: UNITY UNIVERSITY ADAMA SPECIAL CAMPUS
C7: BUAD/09 FIRST SEM 2017 Cont.ASSESSMENTFORM
B9: COURSE TITLE:OPERATION AND PRODUCTION MANAGEMENT | D9: COURSE NO: | F9: MGMT331
A10: NO. | B10: NAME | C10: ID.NO | D10: Monthly Test | G10: ASSIGNMENT | I10: Attend | J10: Total | K10: Final | L10: Total | M10: Grade
D11: 0.1 | E11: 0.1 | F11: 0.1 | G11: Ind(10%) | H11: Team(5%) | I11: 0.05 | J11: 0.5 | K11: 0.5 | L11: 1
A12: 1 | B12: ABERAR AMDELA | C12: 45488/08
A13: 2 | B13: BETELHEM ASHENAFI | C13: 45276/08
A14: 3 | B14: DANIEL KIFLE | C14: 45480/08
A15: 4 | B15: FAIZA MOHAMMED | C15: 45624/08
A16: 5 | B16: FIKIRU SIME | C16: 45504/08
A17: 6 | B17: FIRAOL ABERHAM | C17: 45460/08
A18: 7 | B18: HANA DESALEGN | C18: 45511/08
A19: 8 | B19: HANAN SANI | C19: 45520/08
A20: 9 | B20: HAWI MOHAMMED | C20: 45454/08
A21: 10 | B21: HELDANA GEBRU | C21: 45223/08
A22: 11 | B22: HUSINIYA KEDIR | C22: 45512/08
A23: 12 | B23: KIDUS BEHAILU | C23: 45623/08
... A30: 19 | B30: YEABSIRA GETACHEW | C30: 45622/08
A31: 20
A32: 21
A33: 22
A34: 23
C35: ADD STUDENTS
A36: 1 | B36: ASFAWESEN MELESE | C36: 45560/08
A37: 2
A38: 3
A39: 4
A40: 5
C44: UNITY UNIVERSITY ADAMA SPECIAL CAMPUS
C45: BUAD/09 FIRST SEM 2017 Cont.ASSESSMENTFORM
B47: COURSE TITLE:SYSTEM ANALYSIS &DESIGN | D47: COURSE NO: | F47: MGMT421
A48: NO. | B48: NAME | C48: ID.NO | D48: Monthly Test | G48: ASSIGNMENT | I48: Attend | J48: Total | K48: Final | L48: Total | M48: Grade
D49: 0.1 | E49: 0.1 | F49: 0.1 | G49: Ind(10%) | H49: Team(5%) | I49: 0.05 | J49: 0.5 | K49: 0.5 | L49: 1
A50: 1 | B50: ABERAR AMDELA | C50: 45488/08
A51: 2 | B51: BETELHEM ASHENAFI | C51: 45276/08
A52: 3 | B52: DANIEL KIFLE | C52: 45480/08
A53: 4 | B53: FAIZA MOHAMMED | C53: 45624/08
A54: 5 | B54: FIKIRU SIME | C54: 45504/08
A55: 6 | B55: FIRAOL ABERHAM | C55: 45460/08
A56: 7 | B56: HANA DESALEGN | C56: 45511/08
...

Sheet GRS-BUAD-MRKT-MGMT-EX-08
C1: UNITY UNIVERSITY
C2: ADAMA SPECIAL CAMPUS
C3: OFFICE OF REGISTRAR
C4: GRADE SUBMISION FORM
C5: YEAR III SEM II/2018 | H5: YEAR III SEM I/2017 | I5: =C5 -> YEAR III SEM II/2018
C6: COURSE TITLE: | H6: COURSE TITLE:
C7: STRATEGIC MANAGEMENT | H7: =C6 -> COURSE TITLE: | I7: =C7 -> STRATEGIC MANAGEMENT
C8: COURSENO.MGMT412 | H8: COURSE NO.Mgmt412
C9: SECTION:BUAD/R/08 | H9: SECTION:BUAD/R/08
B10: S.N | C10: STUDENTS NAME | D10: ID.NO | E10: GRADE | I10: ID.NO | J10: GRADE | K10: GRADE
B11: 1 | C11: ABERAR AMDELA | D11: 45488/08 | I11: =D11 -> 45488/08
B12: 2 | C12: BETELHEM ASHENAFI | D12: 45276/08 | F12: Grade Summary | I12: =D12 -> 45276/08
B13: 3 | C13: DANIEL KIFLE | D13: 45480/08 | F13: A+'S------ | I13: =D13 -> 45480/08
B14: 4 | C14: ELIAS FIKADU | D14: 00012/08 | F14: A'S | I14: =D14 -> 00012/08
B15: 5 | C15: FAIZA MOHAMMED | D15: 45624/08 | F15: B+'S----- | I15: =D15 -> 45624/08
B16: 6 | C16: FIKIRU SIME | D16: 45504/08 | F16: B'S------- | I16: =D16 -> 45504/08
B17: 7 | C17: FIRAOL ABERHAM | D17: 45460/09 | F17: C+'S----- | I17: =D17 -> 45460/09
B18: 8 | C18: HANA DESALEGN | D18: 45511/08 | F18: C'S------ | I18: =D18 -> 45511/08
B19: 9 | C19: HANAN SANI | D19: 45520/08 | F19: D'S------ | I19: =D19 -> 45520/08
B20: 10 | C20: HAWI MOHAMMED | D20: 45459/08 | F20: NG'S----- | I20: =D20 -> 45459/08
B21: 11 | C21: HELDANA GEBRU | D21: 45223/08 | F21: I'S-------- | I21: =D21 -> 45223/08
B22: 12 | C22: HUSINIYA KEDIR | D22: 45312/08 | F22: TOT----- | I22: =D22 -> 45312/08
B23: 13 | C23: MAHADER AYALEW | D23: 45586/08 | I23: =D23 -> 45586/08
B24: 14 | C24: MAHADER GETACHEW | D24: 45509/08 | I24: =D24 -> 45509/08
B25: 15 | C25: MEHRET MELESE | D25: 45514/08 | I25: =D25 -> 45514/08
B26: 16 | C26: MIKIAS MULUGETA | D26: 45503/08 | I26: =D26 -> 45503/08
B27: 17 | C27: REDIET SEYOUM | D27: 45505/08 | I27: =D27 -> 45505/08
B28: 18 | C28: TSEGENT ZERIHUN | D28: 45517/08 | I28: =D28 -> 45517/08
B29: 19 | C29: YEABSIRA GETACHEW | D29: 45622/08 | I29: =D29 -> 45622/08
B30: 20 | C30: WOINSHET AMSALU | D30: 45502/08 | I30: =D30 -> 45502/08
C31: ADD STUDENTS | I31: ADD STUDENTS
B32: 1 | C32: ASFAWESEN MELESE | D32: 45560/08 | I32: 45560/08
B33: 2 | C33: BANDAMLAK ASSEFA | D33: 201/02 | I33: 201/02
B34: 3 | C34: NOBEL ASSEFA | D34: 45578/08 | I34: 45578/08
B35: 4
B36: 5
C37: INST.NAME__________________ | D37: SIGNATURE________________ | F37: ____________
C38: DATE-____________________
C40: DEP.HEAD NAME______________ | D40: SIGNATUE___________________
C41: DATE:___________________
...

Sheet ATT-COSC--R-14-SEC-1
A1: COSC/R/14
A2: UNITY UNIVERSITY ADAMA CAMPUS
A3: COSC/R/14 Year II Semester II 2023 (2015 E.C) ATTENDANCE FORM
A5: COURSE TITLE: Basic Electricity & Electronics COURSE NO: Phys 2042 SEC-1 INSTRUCTOR:
A6: NO. | B6: NAME | E6: ID.NO
A7: 1 | B7: ABENEZER | C7: DABI | D7: BALCHA | E7: 04529/14
A8: 2 | B8: AMANUEL | C8: BELETE | D8: BEKELE | E8: 04516/14
A9: 3 | B9: AYUB | C9: ABDULAHAFIZ | D9: TADESSE | E9: 04636/14
A10: 4 | B10: BEMNET | C10: WEGAYEHU | D10: IJEGU | E10: 04525/14
A11: 5 | B11: BETHELIHEM | C11: BELAY | D11: SHIFERAW | E11: 04522/14
A12: 6 | B12: DANIEL | C12: KASAYE | D12: KIDANE | E12: 04494/14
A13: 7 | B13: DAWIT | C13: AYELE | D13: MASSA | E13: 04136/14
A14: 8 | B14: EDOM | C14: NIGUSSIE | D14: ASSEFA | E14: 06120/14
A15: 9 | B15: ELIAB | C15: WOUBISHET | D15: GETACHEW | E15: 04493/14
A16: 10 | B16: ERMIAS | C16: ASSAYE | D16: NEDI | E16: 04510/14
A17: 11 | B17: ESMAEL | C17: ALI | D17: MOHAMMED | E17: 04518/14
A18: 12 | B18: EYOBED | C18: ALEMU | D18: HABEBE | E18: 04515/14
... A40: 34 | B40: YOSEF | C40: TILAYE | D40: ZENEBE | E40: 04470/14
A41: ADD STUDENTS
A42: NO. | B42: STUDENTS NAME | E42: ID.NO
A43: 1 | B43: KHALID | C43: KHELIL | D43: ABDUREHAMAN | E43: 04743/13
A44: 2
A45: 3
A46: 4
A47: 5
A48: UNITY UNIVERSITY ADAMA CAMPUS
A49: COSC/R/14 Year II Semester II 2023 (2015 E.C) ATTENDANCE FORM
A51: COURSE TITLE: Linear Algebra COURSE NO: Math 2022 SEC-1 INSTRUCTOR:
A52: NO. | B52: STUDENTS NAME | E52: ID.NO
A53: 1 | B53: ABENEZER | C53: DABI | D53: BALCHA | E53: 04529/14
A54: 2 | B54: AMANUEL | C54: BELETE | D54: BEKELE | E54: 04516/14
A55: 3 | B55: AYUB | C55: ABDULAHAFIZ | D55: TADESSE | E55: 04636/14
A56: 4 | B56: BEMNET | C56: WEGAYEHU | D56: IJEGU | E56: 04525/14
A57: 5 | B57: BETHELIHEM | C57: BELAY | D57: SHIFERAW | E57: 04522/14
A58: 6 | B58: DANIEL | C58: KASAYE | D58: KIDANE | E58: 04494/14
A59: 7 | B59: DAWIT | C59: AYELE | D59: MASSA | E59: 04136/14
A60: 8 | B60: EDOM | C60: NIGUSSIE | D60: ASSEFA | E60: 06120/14
A61: 9 | B61: ELIAB | C61: WOUBISHET | D61: GETACHEW | E61: 04493/14
A62: 10 | B62: ERMIAS | C62: ASSAYE | D62: NEDI | E62: 04510/14
A63: 11 | B63: ESMAEL | C63: ALI | D63: MOHAMMED | E63: 04518/14
...

Sheet CONN-COSC-R-14-SEC-1
A1: COSC/REG/14
A3: UNITY UNIVERSITY ADAMA CAMPUS
A4: COSC/R/14 Year II Semester II 2023 (2015 E.C) Cont.ASSESSMENT FORM
A51: UNITY UNIVERSITY ADAMA SPECIAL CAMPUS
A52: COSC/R/14 Year II Semester II 2023 (2015 E.C) Cont.ASSESSMENT FORM
A54: ='ATT-COSC--R-14-SEC-1'!A51 -> COURSE TITLE: Linear Algebra COURSE NO: Math 2022 SEC-1 INSTRUCTOR: | J54: Sisay K.
A55: NO. | B55: NAME | E55: ID.NO | F55: Test | H55: ASSIGNMENT | J55: Attend | K55: Total | L55: Final | M55: Total | N55: Grade
F56: 0.05 | G56: 0.15 | H56: Ind.(10%) | I56: Team(15%) | J56: 0.05 | K56: 0.5 | L56: 0.5 | M56: 1
A57: ='ATT-COSC--R-14-SEC-1'!A53 -> 1 | E57: ='ATT-COSC--R-14-SEC-1'!E53 -> 04529/14 | F57: 5 | G57: 15 | H57: 10 | I57: 15 | J57: 5 | K57: =SUM(F57:J57) -> 50 | L57: 33.5 | M57: =SUM(K57:L57) -> 83.5
A58: ='ATT-COSC--R-14-SEC-1'!A54 -> 2 | E58: ='ATT-COSC--R-14-SEC-1'!E54 -> 04516/14 | F58: 5 | G58: 5 | H58: 10 | I58: 15 | J58: 5 | K58: =SUM(F58:J58) -> 40 | L58: 12.5 | M58: =SUM(K58:L58) -> 52.5
A59: ='ATT-COSC--R-14-SEC-1'!A55 -> 3 | E59: ='ATT-COSC--R-14-SEC-1'!E55 -> 04636/14 | F59: 0 | G59: 8 | I59: 14 | J59: 3 | K59: =SUM(F59:J59) -> 25 | L59: 10 | M59: =SUM(K59:L59) -> 35
A60: ='ATT-COSC--R-14-SEC-1'!A56 -> 4 | E60: ='ATT-COSC--R-14-SEC-1'!E56 -> 04525/14 | F60: 0 | G60: 7 | H60: 9 | J60: 5 | K60: =SUM(F60:J60) -> 21 | L60: 15 | M60: =SUM(K60:L60) -> 36
A61: ='ATT-COSC--R-14-SEC-1'!A57 -> 5 | E61: ='ATT-COSC--R-14-SEC-1'!E57 -> 04522/14 | F61: 5 | G61: 13 | H61: 9 | I61: 15 | J61: 5 | K61: =SUM(F61:J61) -> 47 | L61: 27 | M61: =SUM(K61:L61) -> 74
A62: ='ATT-COSC--R-14-SEC-1'!A58 -> 6 | E62: ='ATT-COSC--R-14-SEC-1'!E58 -> 04494/14 | F62: 5 | G62: 3 | H62: 8 | I62: 15 | J62: 5 | K62: =SUM(F62:J62) -> 36 | L62: 2.5 | M62: =SUM(K62:L62) -> 38.5
A63: ='ATT-COSC--R-14-SEC-1'!A59 -> 7 | E63: ='ATT-COSC--R-14-SEC-1'!E59 -> 04136/14 | F63: 5 | G63: 7 | H63: 9.5 | I63: 15 | J63: 5 | K63: =SUM(F63:J63) -> 41.5 | L63: 11.5 | M63: =SUM(K63:L63) -> 53
A64: ='ATT-COSC--R-14-SEC-1'!A60 -> 8 | E64: ='ATT-COSC--R-14-SEC-1'!E60 -> 06120/14 | F64: 5 | G64: 9.5 | H64: 6 | I64: 15 | J64: 5 | K64: =SUM(F64:J64) -> 40.5 | L64: 18.5 | M64: =SUM(K64:L64) -> 59
A65: ='ATT-COSC--R-14-SEC-1'!A61 -> 9 | E65: ='ATT-COSC--R-14-SEC-1'!E61 -> 04493/14 | F65: 5 | G65: 1 | H65: 10 | I65: 14.5 | J65: 5 | K65: =SUM(F65:J65) -> 35.5 | L65: 5 | M65: =SUM(K65:L65) -> 40.5
A66: ='ATT-COSC--R-14-SEC-1'!A62 -> 10 | E66: ='ATT-COSC--R-14-SEC-1'!E62 -> 04510/14 | F66: 0 | G66: 5 | H66: 9 | I66: 15 | J66: 4 | K66: =SUM(F66:J66) -> 33 | L66: 12.5 | M66: =SUM(K66:L66) -> 45.5
A67: ='ATT-COSC--R-14-SEC-1'!A63 -> 11 | E67: ='ATT-COSC--R-14-SEC-1'!E63 -> 04518/14 | F67: 5 | G67: 4 | H67: 8 | I67: 14.5 | J67: 5 | K67: =SUM(F67:J67) -> 36.5 | L67: 2.5 | M67: =SUM(K67:L67) -> 39
A68: ='ATT-COSC--R-14-SEC-1'!A64 -> 12 | E68: ='ATT-COSC--R-14-SEC-1'!E64 -> 04515/14 | F68: 5 | G68: 3 | H68: 9 | I68: 15 | J68: 5 | K68: =SUM(F68:J68) -> 37 | L68: 5 | M68: =SUM(K68:L68) -> 42
A69: ='ATT-COSC--R-14-SEC-1'!A65 -> 13 | E69: ='ATT-COSC--R-14-SEC-1'!E65 -> 04501/14 | F69: 5 | G69: 7.5 | H69: 8 | I69: 14.5 | J69: 5 | K69: =SUM(F69:J69) -> 40 | L69: 8 | M69: =SUM(K69:L69) -> 48
A70: ='ATT-COSC--R-14-SEC-1'!A66 -> 14 | E70: ='ATT-COSC--R-14-SEC-1'!E66 -> 04500/14 | F70: 0 | G70: 7 | I70: 14.5 | J70: 5 | K70: =SUM(F70:J70) -> 26.5 | L70: 10 | M70: =SUM(K70:L70) -> 36.5
A71: ='ATT-COSC--R-14-SEC-1'!A67 -> 15 | E71: ='ATT-COSC--R-14-SEC-1'!E67 -> 04540/14 | F71: 0 | H71: 5 | I71: 15 | J71: 5 | K71: =SUM(F71:J71) -> 25 | M71: =SUM(K71:L71) -> 25 | N71: I
A72: ='ATT-COSC--R-14-SEC-1'!A68 -> 16 | E72: ='ATT-COSC--R-14-SEC-1'!E68 -> 04622/14 | F72: 0 | G72: 9 | H72: 9 | I72: 15 | J72: 4 | K72: =SUM(F72:J72) -> 37 | L72: 0 | M72: =SUM(K72:L72) -> 37
A73: ='ATT-COSC--R-14-SEC-1'!A69 -> 17 | E73: ='ATT-COSC--R-14-SEC-1'!E69 -> 04513/14 | F73: 5 | G73: 15 | H73: 10 | I73: 15 | J73: 5 | K73: =SUM(F73:J73) -> 50 | L73: 35 | M73: =SUM(K73:L73) -> 85
A74: ='ATT-COSC--R-14-SEC-1'!A70 -> 18 | E74: ='ATT-COSC--R-14-SEC-1'!E70 -> 04523/14 | F74: 0 | G74: 5 | H74: 9 | I74: 15 | J74: 5 | K74: =SUM(F74:J74) -> 34 | L74: 2.5 | M74: =SUM(K74:L74) -> 36.5
A75: ='ATT-COSC--R-14-SEC-1'!A71 -> 19 | E75: ='ATT-COSC--R-14-SEC-1'!E71 -> 04507/14 | F75: 5 | G75: 10.5 | H75: 9 | I75: 14 | J75: 5 | K75: =SUM(F75:J75) -> 43.5 | L75: 30.5 | M75: =SUM(K75:L75) -> 74
A76: ='ATT-COSC--R-14-SEC-1'!A72 -> 20 | E76: ='ATT-COSC--R-14-SEC-1'!E72 -> 06063/14 | F76: 0 | G76: 5 | H76: 5 | J76: 4 | K76: =SUM(F76:J76) -> 14 | M76: =SUM(K76:L76) -> 14 | N76: I
A77: ='ATT-COSC--R-14-SEC-1'!A73 -> 21 | E77: ='ATT-COSC--R-14-SEC-1'!E73 -> 04509/14 | F77: 5 | G77: 3 | H77: 8 | I77: 14 | J77: 5 | K77: =SUM(F77:J77) -> 35 | L77: 7.5 | M77: =SUM(K77:L77) -> 42.5
A78: ='ATT-COSC--R-14-SEC-1'!A74 -> 22 | E78: ='ATT-COSC--R-14-SEC-1'!E74 -> 04512/14 | F78: 5 | G78: 10 | H78: 9 | I78: 15 | J78: 5 | K78: =SUM(F78:J78) -> 44 | L78: 5 | M78: =SUM(K78:L78) -> 49
A79: ='ATT-COSC--R-14-SEC-1'!A75 -> 23 | E79: ='ATT-COSC--R-14-SEC-1'!E75 -> 04727/14 | F79: 0 | G79: 4 | H79: 5 | I79: 14.5 | J79: 3 | K79: =SUM(F79:J79) -> 26.5 | L79: 7.5 | M79: =SUM(K79:L79) -> 34
A80: ='ATT-COSC--R-14-SEC-1'!A76 -> 24 | E80: ='ATT-COSC--R-14-SEC-1'!E76 -> 04498/14 | F80: 5 | G80: 11 | H80: 9.5 | I80: 15 | J80: 5 | K80: =SUM(F80:J80) -> 45.5 | L80: 31 | M80: =SUM(K80:L80) -> 76.5
A81: ='ATT-COSC--R-14-SEC-1'!A77 -> 25 | E81: ='ATT-COSC--R-14-SEC-1'!E77 -> 04538/14 | F81: 0 | G81: 9.5 | H81: 9 | I81: 15 | J81: 5 | K81: =SUM(F81:J81) -> 38.5 | L81: 9.5 | M81: =SUM(K81:L81) -> 48
A82: ='ATT-COSC--R-14-SEC-1'!A78 -> 26 | E82: ='ATT-COSC--R-14-SEC-1'!E78 -> 04539/14 | F82: 0 | G82: 9.5 | I82: 15 | J82: 4 | K82: =SUM(F82:J82) -> 28.5 | L82: 7.5 | M82: =SUM(K82:L82) -> 36
A83: ='ATT-COSC--R-14-SEC-1'!A79 -> 27 | E83: ='ATT-COSC--R-14-SEC-1'!E79 -> 06064/13 | F83: 0 | G83: 7.5 | H83: 9.5 | I83: 13 | J83: 5 | K83: =SUM(F83:J83) -> 35 | L83: 5 | M83: =SUM(K83:L83) -> 40
A84: ='ATT-COSC--R-14-SEC-1'!A80 -> 28 | E84: ='ATT-COSC--R-14-SEC-1'!E80 -> 06123/23 | F84: 5 | G84: 10.5 | H84: 10 | I84: 15 | J84: 5 | K84: =SUM(F84:J84) -> 45.5 | L84: 21.5 | M84: =SUM(K84:L84) -> 67
A85: ='ATT-COSC--R-14-SEC-1'!A81 -> 29 | E85: ='ATT-COSC--R-14-SEC-1'!E81 -> 04502/14 | F85: 5 | G85: 15 | H85: 10 | I85: 14 | J85: 5 | K85: =SUM(F85:J85) -> 49 | L85: 45 | M85: =SUM(K85:L85) -> 94
A86: ='ATT-COSC--R-14-SEC-1'!A82 -> 30 | E86: ='ATT-COSC--R-14-SEC-1'!E82 -> 04497/14 | F86: 5 | G86: 4 | H86: 7 | I86: 14 | J86: 5 | K86: =SUM(F86:J86) -> 35 | L86: 14.5 | M86: =SUM(K86:L86) -> 49.5
A87: ='ATT-COSC--R-14-SEC-1'!A83 -> 31 | E87: ='ATT-COSC--R-14-SEC-1'!E83 -> 04508/14 | F87: 5 | G87: 7 | H87: 8 | I87: 14.5 | J87: 4 | K87: =SUM(F87:J87) -> 38.5 | L87: 12.5 | M87: =SUM(K87:L87) -> 51
A88: ='ATT-COSC--R-14-SEC-1'!A84 -> 32 | E88: ='ATT-COSC--R-14-SEC-1'!E84 -> 04499/14 | F88: 0 | G88: 14 | H88: 9.5 | I88: 14.5 | J88: 5 | K88: =SUM(F88:J88) -> 43 | L88: 40.5 | M88: =SUM(K88:L88) -> 83.5
...

Sheet GRS-COSC-R-14-SEC-1
A1: COSC/REG/14
A2: UNITY UNIVERSITY
A3: ADAMA CAMPUS
A4: OFFICE OF REGISTRAR
A5: GRADE SUBMISSION FORM
A6: Year II Semester II 2023 | H6: =A6 -> Year II Semester II 2023
A7: COURSE TITLE: Basic Electricity & Electronics | H7: =A7 -> COURSE TITLE: Basic Electricity & Electronics
A8: COURSE NO: Phys 2042 | H8: =A8 -> COURSE NO: Phys 2042
A9: SECTION: COSC/R/14-1 | H9: =A9 -> SECTION: COSC/R/14-1
A10: INSTRUCTOR: | H10: =A10 -> INSTRUCTOR:
A11: S.N | B11: STUDENTS NAME | D11: ID.NO | E11: GRADE | I11: ID.NO | J11: GRADE
A12: ='CONN-COSC-R-14-SEC-1'!A9 -> 0 | B12: ='CONN-COSC-R-14-SEC-1'!B9 -> 0 | C12: ='CONN-COSC-R-14-SEC-1'!C9 -> 0 | D12: ='CONN-COSC-R-14-SEC-1'!E9 -> 0 | I12: =D12 -> 0
A13: ='CONN-COSC-R-14-SEC-1'!A10 -> 0 | B13: ='CONN-COSC-R-14-SEC-1'!B10 -> 0 | C13: ='CONN-COSC-R-14-SEC-1'!C10 -> 0 | D13: ='CONN-COSC-R-14-SEC-1'!E10 -> 0 | I13: =D13 -> 0
A14: ='CONN-COSC-R-14-SEC-1'!A11 -> 0 | B14: ='CONN-COSC-R-14-SEC-1'!B11 -> 0 | C14: ='CONN-COSC-R-14-SEC-1'!C11 -> 0 | D14: ='CONN-COSC-R-14-SEC-1'!E11 -> 0 | I14: =D14 -> 0
A15: ='CONN-COSC-R-14-SEC-1'!A12 -> 0 | B15: ='CONN-COSC-R-14-SEC-1'!B12 -> 0 | C15: ='CONN-COSC-R-14-SEC-1'!C12 -> 0 | D15: ='CONN-COSC-R-14-SEC-1'!E12 -> 0 | F15: Grade Summary | I15: =D15 -> 0
A16: ='CONN-COSC-R-14-SEC-1'!A13 -> 0 | B16: ='CONN-COSC-R-14-SEC-1'!B13 -> 0 | C16: ='CONN-COSC-R-14-SEC-1'!C13 -> 0 | D16: ='CONN-COSC-R-14-SEC-1'!E13 -> 0 | F16: A+'S------ | I16: =D16 -> 0
A17: ='CONN-COSC-R-14-SEC-1'!A14 -> 0 | B17: ='CONN-COSC-R-14-SEC-1'!B14 -> 0 | C17: ='CONN-COSC-R-14-SEC-1'!C14 -> 0 | D17: ='CONN-COSC-R-14-SEC-1'!E14 -> 0 | F17: A'S | I17: =D17 -> 0
A18: ='CONN-COSC-R-14-SEC-1'!A15 -> 0 | B18: ='CONN-COSC-R-14-SEC-1'!B15 -> 0 | C18: ='CONN-COSC-R-14-SEC-1'!C15 -> 0 | D18: ='CONN-COSC-R-14-SEC-1'!E15 -> 0 | F18: B+'S----- | I18: =D18 -> 0
A19: ='CONN-COSC-R-14-SEC-1'!A16 -> 0 | B19: ='CONN-COSC-R-14-SEC-1'!B16 -> 0 | C19: ='CONN-COSC-R-14-SEC-1'!C16 -> 0 | D19: ='CONN-COSC-R-14-SEC-1'!E16 -> 0 | F19: B'S------- | I19: =D19 -> 0
A20: ='CONN-COSC-R-14-SEC-1'!A17 -> 0 | B20: ='CONN-COSC-R-14-SEC-1'!B17 -> 0 | C20: ='CONN-COSC-R-14-SEC-1'!C17 -> 0 | D20: ='CONN-COSC-R-14-SEC-1'!E17 -> 0 | F20: C+'S----- | I20: =D20 -> 0
A21: ='CONN-COSC-R-14-SEC-1'!A18 -> 0 | B21: ='CONN-COSC-R-14-SEC-1'!B18 -> 0 | C21: ='CONN-COSC-R-14-SEC-1'!C18 -> 0 | D21: ='CONN-COSC-R-14-SEC-1'!E18 -> 0 | F21: C'S------ | I21: =D21 -> 0
A22: ='CONN-COSC-R-14-SEC-1'!A19 -> 0 | B22: ='CONN-COSC-R-14-SEC-1'!B19 -> 0 | C22: ='CONN-COSC-R-14-SEC-1'!C19 -> 0 | D22: ='CONN-COSC-R-14-SEC-1'!E19 -> 0 | F22: NG'S----- | I22: =D22 -> 0
A23: ='CONN-COSC-R-14-SEC-1'!A20 -> 0 | B23: ='CONN-COSC-R-14-SEC-1'!B20 -> 0 | C23: ='CONN-COSC-R-14-SEC-1'!C20 -> 0 | D23: ='CONN-COSC-R-14-SEC-1'!E20 -> 0 | F23: D'S------ | I23: =D23 -> 0
A24: ='CONN-COSC-R-14-SEC-1'!A21 -> 0 | B24: ='CONN-COSC-R-14-SEC-1'!B21 -> 0 | C24: ='CONN-COSC-R-14-SEC-1'!C21 -> 0 | D24: ='CONN-COSC-R-14-SEC-1'!E21 -> 0 | F24: I'S-------- | I24: =D24 -> 0
A25: ='CONN-COSC-R-14-SEC-1'!A22 -> 0 | B25: ='CONN-COSC-R-14-SEC-1'!B22 -> 0 | C25: ='CONN-COSC-R-14-SEC-1'!C22 -> 0 | D25: ='CONN-COSC-R-14-SEC-1'!E22 -> 0 | F25: F'S------- | I25: =D25 -> 0
A26: ='CONN-COSC-R-14-SEC-1'!A23 -> 0 | B26: ='CONN-COSC-R-14-SEC-1'!B23 -> 0 | C26: ='CONN-COSC-R-14-SEC-1'!C23 -> 0 | D26: ='CONN-COSC-R-14-SEC-1'!E23 -> 0 | F26: TOTAL------ | I26: =D26 -> 0
A27: ='CONN-COSC-R-14-SEC-1'!A24 -> 0 | B27: ='CONN-COSC-R-14-SEC-1'!B24 -> 0 | C27: ='CONN-COSC-R-14-SEC-1'!C24 -> 0 | D27: ='CONN-COSC-R-14-SEC-1'!E24 -> 0 | I27: =D27 -> 0
A28: ='CONN-COSC-R-14-SEC-1'!A25 -> 0 | B28: ='CONN-COSC-R-14-SEC-1'!B25 -> 0 | C28: ='CONN-COSC-R-14-SEC-1'!C25 -> 0 | D28: ='CONN-COSC-R-14-SEC-1'!E25 -> 0 | I28: =D28 -> 0
A29: ='CONN-COSC-R-14-SEC-1'!A26 -> 0 | B29: ='CONN-COSC-R-14-SEC-1'!B26 -> 0 | C29: ='CONN-COSC-R-14-SEC-1'!C26 -> 0 | D29: ='CONN-COSC-R-14-SEC-1'!E26 -> 0 | I29: =D29 -> 0
A30: ='CONN-COSC-R-14-SEC-1'!A27 -> 0 | B30: ='CONN-COSC-R-14-SEC-1'!B27 -> 0 | C30: ='CONN-COSC-R-14-SEC-1'!C27 -> 0 | D30: ='CONN-COSC-R-14-SEC-1'!E27 -> 0 | I30: =D30 -> 0
A31: ='CONN-COSC-R-14-SEC-1'!A28 -> 0 | B31: ='CONN-COSC-R-14-SEC-1'!B28 -> 0 | C31: ='CONN-COSC-R-14-SEC-1'!C28 -> 0 | D31: ='CONN-COSC-R-14-SEC-1'!E28 -> 0 | I31: =D31 -> 0
A32: ='CONN-COSC-R-14-SEC-1'!A29 -> 0 | B32: ='CONN-COSC-R-14-SEC-1'!B29 -> 0 | C32: ='CONN-COSC-R-14-SEC-1'!C29 -> 0 | D32: ='CONN-COSC-R-14-SEC-1'!E29 -> 0 | I32: =D32 -> 0
A33: ='CONN-COSC-R-14-SEC-1'!A30 -> 0 | B33: ='CONN-COSC-R-14-SEC-1'!B30 -> 0 | C33: ='CONN-COSC-R-14-SEC-1'!C30 -> 0 | D33: ='CONN-COSC-R-14-SEC-1'!E30 -> 0 | I33: =D33 -> 0
A34: ='CONN-COSC-R-14-SEC-1'!A31 -> 0 | B34: ='CONN-COSC-R-14-SEC-1'!B31 -> 0 | C34: ='CONN-COSC-R-14-SEC-1'!C31 -> 0 | D34: ='CONN-COSC-R-14-SEC-1'!E31 -> 0 | I34: =D34 -> 0
A35: ='CONN-COSC-R-14-SEC-1'!A32 -> 0 | B35: ='CONN-COSC-R-14-SEC-1'!B32 -> 0 | C35: ='CONN-COSC-R-14-SEC-1'!C32 -> 0 | D35: ='CONN-COSC-R-14-SEC-1'!E32 -> 0 | I35: =D35 -> 0
A36: ='CONN-COSC-R-14-SEC-1'!A33 -> 0 | B36: ='CONN-COSC-R-14-SEC-1'!B33 -> 0 | C36: ='CONN-COSC-R-14-SEC-1'!C33 -> 0 | D36: ='CONN-COSC-R-14-SEC-1'!E33 -> 0 | I36: =D36 -> 0
A37: ='CONN-COSC-R-14-SEC-1'!A34 -> 0 | B37: ='CONN-COSC-R-14-SEC-1'!B34 -> 0 | C37: ='CONN-COSC-R-14-SEC-1'!C34 -> 0 | D37: ='CONN-COSC-R-14-SEC-1'!E34 -> 0 | I37: =D37 -> 0
A38: ='CONN-COSC-R-14-SEC-1'!A35 -> 0 | B38: ='CONN-COSC-R-14-SEC-1'!B35 -> 0 | C38: ='CONN-COSC-R-14-SEC-1'!C35 -> 0 | D38: ='CONN-COSC-R-14-SEC-1'!E35 -> 0 | I38: =D38 -> 0
... A44: ='CONN-COSC-R-14-SEC-1'!A41 -> 0 | B44: ='CONN-COSC-R-14-SEC-1'!B41 -> 0 | C44: ='CONN-COSC-R-14-SEC-1'!C41 -> 0 | D44: ='CONN-COSC-R-14-SEC-1'!E41 -> 0 | I44: =D44 -> 0
A45: ADD STUDENTS | I45: ADD STUDENTS
...

Sheet ATT-COSC-R-14-SEC-2
A1: COSC/REG/14
A2: UNITY UNIVERSITY ADAMA CAMPUS
A3: COSC/R/14 Year II Semester II 2023 (2015 E.C) ATTENDANCE FORM
A5: COURSE TITLE: Basic Electricity & Electronics COURSE NO: Phys 2042 SEC-2 INSTRUCTOR:
A6: NO. | B6: STUDENTS NAME | E6: ID.NO
A7: 1 | B7: ABEL | C7: MESFIN | D7: SEBOKA | E7: 04575/14
A8: 2 | B8: ABEL | C8: TAMIRU | D8: TEKELESILASE | E8: 04472/14
A9: 3 | B9: AMANUEL | C9: BUKUNE | D9: TESEMA | E9: 04521/14
A10: 4 | B10: AMIR | C10: AHMED | D10: BELAYNESH | E10: 04552/14
A11: 5 | B11: BEAMLAK | C11: TECHANE | D11: MEKONIN | E11: 04563/14
A12: 6 | B12: BINIYAM | C12: MULAT | D12: TEGESHE | E12: 04565/14
A13: 7 | B13: DAWIT | C13: KETEMA | D13: TADESSE | E13: 04537/14
A14: 8 | B14: EYUEL | C14: ABIYOT | D14: FELEKE | E14: 04570/14
A15: 9 | B15: FAIZ | C15: TEMAM | D15: NURI | E15: 04564/14
A16: 10 | B16: MATIYOS | C16: MARKOS | D16: YOHANNIS | E16: 04548/14
A17: 11 | B17: MELAKU | C17: GENENE | D17: AKLOK | E17: 04549/14
A18: 12 | B18: MICHIAS | C18: ESHEU | D18: MULAT | E18: 04560/14
... A36: 30 | B36: ZELALEM | C36: MULUNEH | D36: DARIYOS | E36: 04559/14
A37: ADD STUDENTS
A38: NO. | B38: STUDENTS NAME | E38: ID.NO
A39: 1 | B39: DEME | C39: TEMESGEN | D39: TOLA | E39: 02588/12
A40: 2 | B40: ELFOLI | C40: ERMIAS | D40: HAILU | E40: 02688/12
A41: 3 | B41: YOHANNES | C41: ASEFA | D41: TEKLU | E41: 02108/12
A42: 4 | B42: YOHANNIS | C42: AKLILU | D42: GASHAW | E42: 02616/12
A43: 5
A44: UNITY UNIVERSITY ADAMA CAMPUS
A45: COSC/R/14 Year II Semester II 2023 (2015 E.C) ATTENDANCE FORM
A47: COURSE TITLE: Linear Algebra COURSE NO: Math 2022 SEC-2 INSTRUCTOR:
A48: NO. | B48: STUDENTS NAME | E48: ID.NO
A49: 1 | B49: ABEL | C49: MESFIN | D49: SEBOKA | E49: 04575/14
A50: 2 | B50: ABEL | C50: TAMIRU | D50: TEKELESILASE | E50: 04472/14
A51: 3 | B51: AMANUEL | C51: BUKUNE | D51: TESEMA | E51: 04521/14
A52: 4 | B52: AMIR | C52: AHMED | D52: BELAYNESH | E52: 04552/14
A53: 5 | B53: BEAMLAK | C53: TECHANE | D53: MEKONIN | E53: 04563/14
A54: 6 | B54: BINIYAM | C54: MULAT | D54: TEGESHE | E54: 04565/14
A55: 7 | B55: DAWIT | C55: KETEMA | D55: TADESSE | E55: 04537/14
A56: 8 | B56: EYUEL | C56: ABIYOT | D56: FELEKE | E56: 04570/14
A57: 9 | B57: FAIZ | C57: TEMAM | D57: NURI | E57: 04564/14
A58: 10 | B58: MATIYOS | C58: MARKOS | D58: YOHANNIS | E58: 04548/14
A59: 11 | B59: MELAKU | C59: GENENE | D59: AKLOK | E59: 04549/14
...

Sheet CONN-COSC-R-14-SEC-2
A1: COSC/REG/14
A3: UNITY UNIVERSITY ADAMA CAMPUS
A4: COSC/R/14 Year II Semester II 2023 (2015 E.C) Cont.ASSESSMENT FORM
A6: ='ATT-COSC-R-14-SEC-2'!A5:Y5 -> COURSE TITLE: Basic Electricity & Electronics COURSE NO: Phys 2042 SEC-2 INSTRUCTOR:
A7: NO. | B7: NAME | E7: ID.NO | H7: ASSIGNMENT | J7: Attend | K7: Total | L7: Final | M7: Total | N7: Grade
G8: 0.1 | H8: Ind.(10%) | I8: Team(5%) | J8: 0.05 | K8: 0.5 | L8: 0.5 | M8: 1
A9: ='ATT-COSC-R-14-SEC-2'!A7 -> 1 | B9: ='ATT-COSC-R-14-SEC-2'!B7 -> ABEL | C9: ='ATT-COSC-R-14-SEC-2'!C7 -> MESFIN | D9: ='ATT-COSC-R-14-SEC-2'!D7 -> SEBOKA | E9: ='ATT-COSC-R-14-SEC-2'!E7 -> 04575/14
A10: ='ATT-COSC-R-14-SEC-2'!A8 -> 2 | B10: ='ATT-COSC-R-14-SEC-2'!B8 -> ABEL | C10: ='ATT-COSC-R-14-SEC-2'!C8 -> TAMIRU | D10: ='ATT-COSC-R-14-SEC-2'!D8 -> TEKELESILASE | E10: ='ATT-COSC-R-14-SEC-2'!E8 -> 04472/14
A11: ='ATT-COSC-R-14-SEC-2'!A9 -> 3 | B11: ='ATT-COSC-R-14-SEC-2'!B9 -> AMANUEL | C11: ='ATT-COSC-R-14-SEC-2'!C9 -> BUKUNE | D11: ='ATT-COSC-R-14-SEC-2'!D9 -> TESEMA | E11: ='ATT-COSC-R-14-SEC-2'!E9 -> 04521/14
A12: ='ATT-COSC-R-14-SEC-2'!A10 -> 4 | B12: ='ATT-COSC-R-14-SEC-2'!B10 -> AMIR | C12: ='ATT-COSC-R-14-SEC-2'!C10 -> AHMED | D12: ='ATT-COSC-R-14-SEC-2'!D10 -> BELAYNESH | E12: ='ATT-COSC-R-14-SEC-2'!E10 -> 04552/14
A13: ='ATT-COSC-R-14-SEC-2'!A11 -> 5 | B13: ='ATT-COSC-R-14-SEC-2'!B11 -> BEAMLAK | C13: ='ATT-COSC-R-14-SEC-2'!C11 -> TECHANE | D13: ='ATT-COSC-R-14-SEC-2'!D11 -> MEKONIN | E13: ='ATT-COSC-R-14-SEC-2'!E11 -> 04563/14
A14: ='ATT-COSC-R-14-SEC-2'!A12 -> 6 | B14: ='ATT-COSC-R-14-SEC-2'!B12 -> BINIYAM | C14: ='ATT-COSC-R-14-SEC-2'!C12 -> MULAT | D14: ='ATT-COSC-R-14-SEC-2'!D12 -> TEGESHE | E14: ='ATT-COSC-R-14-SEC-2'!E12 -> 04565/14
A15: ='ATT-COSC-R-14-SEC-2'!A13 -> 7 | B15: ='ATT-COSC-R-14-SEC-2'!B13 -> DAWIT | C15: ='ATT-COSC-R-14-SEC-2'!C13 -> KETEMA | D15: ='ATT-COSC-R-14-SEC-2'!D13 -> TADESSE | E15: ='ATT-COSC-R-14-SEC-2'!E13 -> 04537/14
A16: ='ATT-COSC-R-14-SEC-2'!A14 -> 8 | B16: ='ATT-COSC-R-14-SEC-2'!B14 -> EYUEL | C16: ='ATT-COSC-R-14-SEC-2'!C14 -> ABIYOT | D16: ='ATT-COSC-R-14-SEC-2'!D14 -> FELEKE | E16: ='ATT-COSC-R-14-SEC-2'!E14 -> 04570/14
A17: ='ATT-COSC-R-14-SEC-2'!A15 -> 9 | B17: ='ATT-COSC-R-14-SEC-2'!B15 -> FAIZ | C17: ='ATT-COSC-R-14-SEC-2'!C15 -> TEMAM | D17: ='ATT-COSC-R-14-SEC-2'!D15 -> NURI | E17: ='ATT-COSC-R-14-SEC-2'!E15 -> 04564/14
A18: ='ATT-COSC-R-14-SEC-2'!A16 -> 10 | B18: ='ATT-COSC-R-14-SEC-2'!B16 -> MATIYOS | C18: ='ATT-COSC-R-14-SEC-2'!C16 -> MARKOS | D18: ='ATT-COSC-R-14-SEC-2'!D16 -> YOHANNIS | E18: ='ATT-COSC-R-14-SEC-2'!E16 -> 04548/14
A19: ='ATT-COSC-R-14-SEC-2'!A17 -> 11 | B19: ='ATT-COSC-R-14-SEC-2'!B17 -> MELAKU | C19: ='ATT-COSC-R-14-SEC-2'!C17 -> GENENE | D19: ='ATT-COSC-R-14-SEC-2'!D17 -> AKLOK | E19: ='ATT-COSC-R-14-SEC-2'!E17 -> 04549/14
A20: ='ATT-COSC-R-14-SEC-2'!A18 -> 12 | B20: ='ATT-COSC-R-14-SEC-2'!B18 -> MICHIAS | C20: ='ATT-COSC-R-14-SEC-2'!C18 -> ESHEU | D20: ='ATT-COSC-R-14-SEC-2'!D18 -> MULAT | E20: ='ATT-COSC-R-14-SEC-2'!E18 -> 04560/14
... A38: ='ATT-COSC-R-14-SEC-2'!A36 -> 30 | B38: ='ATT-COSC-R-14-SEC-2'!B36 -> ZELALEM | C38: ='ATT-COSC-R-14-SEC-2'!C36 -> MULUNEH | D38: ='ATT-COSC-R-14-SEC-2'!D36 -> DARIYOS | E38: ='ATT-COSC-R-14-SEC-2'!E36 -> 04559/14
A39: ADD STUDENTS
A40: NO. | B40: NAME | E40: ID.NO | H40: ASSIGNMENT | J40: Attend | K40: Total | L40: Final | M40: Total | N40: Grade
G41: 0.1 | H41: Ind.(10%) | I41: Team(5%) | J41: 0.05 | K41: 0.5 | L41: 0.5 | M41: 1
A42: 1 | B42: ='ATT-COSC-R-14-SEC-2'!B39 -> DEME | C42: ='ATT-COSC-R-14-SEC-2'!C39 -> TEMESGEN | D42: ='ATT-COSC-R-14-SEC-2'!D39 -> TOLA | E42: ='ATT-COSC-R-14-SEC-2'!E39 -> 02588/12
A43: 2 | B43: ='ATT-COSC-R-14-SEC-2'!B40 -> ELFOLI | C43: ='ATT-COSC-R-14-SEC-2'!C40 -> ERMIAS | D43: ='ATT-COSC-R-14-SEC-2'!D40 -> HAILU | E43: ='ATT-COSC-R-14-SEC-2'!E40 -> 02688/12
A44: 3 | B44: ='ATT-COSC-R-14-SEC-2'!B41 -> YOHANNES | C44: ='ATT-COSC-R-14-SEC-2'!C41 -> ASEFA | D44: ='ATT-COSC-R-14-SEC-2'!D41 -> TEKLU | E44: ='ATT-COSC-R-14-SEC-2'!E41 -> 02108/12
A45: 4 | B45: ='ATT-COSC-R-14-SEC-2'!B42 -> YOHANNIS | C45: ='ATT-COSC-R-14-SEC-2'!C42 -> AKLILU | D45: ='ATT-COSC-R-14-SEC-2'!D42 -> GASHAW | E45: ='ATT-COSC-R-14-SEC-2'!E42 -> 02616/12
A46: 5 | B46: ='ATT-COSC-R-14-SEC-2'!B43 -> 0 | C46: ='ATT-COSC-R-14-SEC-2'!C43 -> 0 | D46: ='ATT-COSC-R-14-SEC-2'!D43 -> 0 | E46: ='ATT-COSC-R-14-SEC-2'!E43 -> 0
A48: UNITY UNIVERSITY ADAMA SPECIAL CAMPUS
A49: COSC/R/14 Year II Semester II 2023 (2015 E.C) Cont.ASSESSMENT FORM
A51: ='ATT-COSC-R-14-SEC-2'!A47 -> COURSE TITLE: Linear Algebra COURSE NO: Math 2022 SEC-2 INSTRUCTOR: | J51: Sisay K.
A52: NO. | B52: NAME | E52: ID.NO | F52: Test | H52: ASSIGNMENT | J52: Attend | K52: Total | L52: Final | M52: Total | N52: Grade
F53: 0.05 | G53: 0.15 | H53: Ind.(10%) | I53: Team(15%) | J53: 0.05 | K53: 0.5 | L53: 0.5 | M53: 1
A54: ='ATT-COSC-R-14-SEC-2'!A49 -> 1 | E54: ='ATT-COSC-R-14-SEC-2'!E49 -> 04575/14 | F54: 5 | G54: 6 | H54: 8 | I54: 14 | J54: 5 | K54: =SUM(F54:J54) -> 38 | L54: 12 | M54: =SUM(K54:L54) -> 50
A55: ='ATT-COSC-R-14-SEC-2'!A50 -> 2 | E55: ='ATT-COSC-R-14-SEC-2'!E50 -> 04472/14 | F55: 0 | G55: 3 | H55: 8 | I55: 14 | J55: 5 | K55: =SUM(F55:J55) -> 30 | L55: 5 | M55: =SUM(K55:L55) -> 35
A56: ='ATT-COSC-R-14-SEC-2'!A51 -> 3 | E56: ='ATT-COSC-R-14-SEC-2'!E51 -> 04521/14 | F56: 5 | G56: 10 | H56: 8 | I56: 14 | J56: 5 | K56: =SUM(F56:J56) -> 42 | L56: 10 | M56: =SUM(K56:L56) -> 52
A57: ='ATT-COSC-R-14-SEC-2'!A52 -> 4 | E57: ='ATT-COSC-R-14-SEC-2'!E52 -> 04552/14 | F57: 5 | G57: 2 | H57: 8 | I57: 14 | J57: 3 | K57: =SUM(F57:J57) -> 32 | L57: 7.5 | M57: =SUM(K57:L57) -> 39.5
A58: ='ATT-COSC-R-14-SEC-2'!A53 -> 5 | E58: ='ATT-COSC-R-14-SEC-2'!E53 -> 04563/14 | F58: 5 | G58: 7 | H58: 9.5 | I58: 15 | J58: 5 | K58: =SUM(F58:J58) -> 41.5 | L58: 22 | M58: =SUM(K58:L58) -> 63.5
A59: ='ATT-COSC-R-14-SEC-2'!A54 -> 6 | E59: ='ATT-COSC-R-14-SEC-2'!E54 -> 04565/14 | F59: 0 | G59: 2 | H59: 7 | I59: 14 | J59: 3 | K59: =SUM(F59:J59) -> 26 | L59: 5 | M59: =SUM(K59:L59) -> 31
A60: ='ATT-COSC-R-14-SEC-2'!A55 -> 7 | E60: ='ATT-COSC-R-14-SEC-2'!E55 -> 04537/14 | F60: 5 | G60: 5 | H60: 8 | I60: 14 | J60: 5 | K60: =SUM(F60:J60) -> 37 | L60: 7.5 | M60: =SUM(K60:L60) -> 44.5
A61: ='ATT-COSC-R-14-SEC-2'!A56 -> 8 | E61: ='ATT-COSC-R-14-SEC-2'!E56 -> 04570/14 | F61: 5 | G61: 12 | H61: 8 | I61: 14 | J61: 5 | K61: =SUM(F61:J61) -> 44 | L61: 25.5 | M61: =SUM(K61:L61) -> 69.5
...

Sheet GRS-COSC-R-14-SEC-2
A1: COSC/REG/14
A2: UNITY UNIVERSITY
A3: ADAMA CAMPUS
A4: OFFICE OF REGISTRAR
A5: GRADE SUBMISSION FORM
A6: Year II Semester II 2023 | H6: =A6 -> Year II Semester II 2023
A7: COURSE TITLE: Basic Electricity & Electronics | H7: =A7 -> COURSE TITLE: Basic Electricity & Electronics
A8: COURSE NO: COSC 2021 | H8: =A8 -> COURSE NO: COSC 2021
A9: SECTION: COSC/R/14-2 | H9: =A9 -> SECTION: COSC/R/14-2
A10: INSTRUCTOR: | H10: =A10 -> INSTRUCTOR:
A11: S.N | B11: STUDENTS NAME | D11: ID.NO | E11: GRADE | I11: ID.NO | J11: GRADE
A12: ='CONN-COSC-R-14-SEC-2'!A9 -> 1 | B12: ='CONN-COSC-R-14-SEC-2'!B9 -> ABEL | C12: ='CONN-COSC-R-14-SEC-2'!C9 -> MESFIN | D12: ='CONN-COSC-R-14-SEC-2'!E9 -> 04575/14 | I12: =D12 -> 04575/14
A13: ='CONN-COSC-R-14-SEC-2'!A10 -> 2 | B13: ='CONN-COSC-R-14-SEC-2'!B10 -> ABEL | C13: ='CONN-COSC-R-14-SEC-2'!C10 -> TAMIRU | D13: ='CONN-COSC-R-14-SEC-2'!E10 -> 04472/14 | I13: =D13 -> 04472/14
A14: ='CONN-COSC-R-14-SEC-2'!A11 -> 3 | B14: ='CONN-COSC-R-14-SEC-2'!B11 -> AMANUEL | C14: ='CONN-COSC-R-14-SEC-2'!C11 -> BUKUNE | D14: ='CONN-COSC-R-14-SEC-2'!E11 -> 04521/14 | I14: =D14 -> 04521/14
A15: ='CONN-COSC-R-14-SEC-2'!A12 -> 4 | B15: ='CONN-COSC-R-14-SEC-2'!B12 -> AMIR | C15: ='CONN-COSC-R-14-SEC-2'!C12 -> AHMED | D15: ='CONN-COSC-R-14-SEC-2'!E12 -> 04552/14 | F15: Grade Summary | I15: =D15 -> 04552/14
A16: ='CONN-COSC-R-14-SEC-2'!A13 -> 5 | B16: ='CONN-COSC-R-14-SEC-2'!B13 -> BEAMLAK | C16: ='CONN-COSC-R-14-SEC-2'!C13 -> TECHANE | D16: ='CONN-COSC-R-14-SEC-2'!E13 -> 04563/14 | F16: A+'S------ | I16: =D16 -> 04563/14
A17: ='CONN-COSC-R-14-SEC-2'!A14 -> 6 | B17: ='CONN-COSC-R-14-SEC-2'!B14 -> BINIYAM | C17: ='CONN-COSC-R-14-SEC-2'!C14 -> MULAT | D17: ='CONN-COSC-R-14-SEC-2'!E14 -> 04565/14 | F17: B+'S----- | I17: =D17 -> 04565/14
A18: ='CONN-COSC-R-14-SEC-2'!A15 -> 7 | B18: ='CONN-COSC-R-14-SEC-2'!B15 -> DAWIT | C18: ='CONN-COSC-R-14-SEC-2'!C15 -> KETEMA | D18: ='CONN-COSC-R-14-SEC-2'!E15 -> 04537/14 | F18: B'S------- | I18: =D18 -> 04537/14
A19: ='CONN-COSC-R-14-SEC-2'!A16 -> 8 | B19: ='CONN-COSC-R-14-SEC-2'!B16 -> EYUEL | C19: ='CONN-COSC-R-14-SEC-2'!C16 -> ABIYOT | D19: ='CONN-COSC-R-14-SEC-2'!E16 -> 04570/14 | F19: C+'S----- | I19: =D19 -> 04570/14
A20: ='CONN-COSC-R-14-SEC-2'!A17 -> 9 | B20: ='CONN-COSC-R-14-SEC-2'!B17 -> FAIZ | C20: ='CONN-COSC-R-14-SEC-2'!C17 -> TEMAM | D20: ='CONN-COSC-R-14-SEC-2'!E17 -> 04564/14 | F20: C'S------ | I20: =D20 -> 04564/14
A21: ='CONN-COSC-R-14-SEC-2'!A18 -> 10 | B21: ='CONN-COSC-R-14-SEC-2'!B18 -> MATIYOS | C21: ='CONN-COSC-R-14-SEC-2'!C18 -> MARKOS | D21: ='CONN-COSC-R-14-SEC-2'!E18 -> 04548/14 | F21: NG'S----- | I21: =D21 -> 04548/14
A22: ='CONN-COSC-R-14-SEC-2'!A19 -> 11 | B22: ='CONN-COSC-R-14-SEC-2'!B19 -> MELAKU | C22: ='CONN-COSC-R-14-SEC-2'!C19 -> GENENE | D22: ='CONN-COSC-R-14-SEC-2'!E19 -> 04549/14 | F22: D'S------ | I22: =D22 -> 04549/14
A23: ='CONN-COSC-R-14-SEC-2'!A20 -> 12 | B23: ='CONN-COSC-R-14-SEC-2'!B20 -> MICHIAS | C23: ='CONN-COSC-R-14-SEC-2'!C20 -> ESHEU | D23: ='CONN-COSC-R-14-SEC-2'!E20 -> 04560/14 | F23: I'S-------- | I23: =D23 -> 04560/14
A24: ='CONN-COSC-R-14-SEC-2'!A21 -> 13 | B24: ='CONN-COSC-R-14-SEC-2'!B21 -> MOHAMMED | C24: ='CONN-COSC-R-14-SEC-2'!C21 -> ABDURAHMAN | D24: ='CONN-COSC-R-14-SEC-2'!E21 -> 04566/14 | F24: F'S------- | I24: =D24 -> 04566/14
A25: ='CONN-COSC-R-14-SEC-2'!A22 -> 14 | B25: ='CONN-COSC-R-14-SEC-2'!B22 -> MULISA | C25: ='CONN-COSC-R-14-SEC-2'!C22 -> TEKLE | D25: ='CONN-COSC-R-14-SEC-2'!E22 -> 04303/14 | F25: TOTAL------ | I25: =D25 -> 04303/14
A26: ='CONN-COSC-R-14-SEC-2'!A23 -> 15 | B26: ='CONN-COSC-R-14-SEC-2'!B23 -> NAFIS | C26: ='CONN-COSC-R-14-SEC-2'!C23 -> SEIFU | D26: ='CONN-COSC-R-14-SEC-2'!E23 -> 04580/14 | I26: =D26 -> 04580/14
A27: ='CONN-COSC-R-14-SEC-2'!A24 -> 16 | B27: ='CONN-COSC-R-14-SEC-2'!B24 -> NOORELDAIM | C27: ='CONN-COSC-R-14-SEC-2'!C24 -> ZEINU | D27: ='CONN-COSC-R-14-SEC-2'!E24 -> 04637/14 | I27: =D27 -> 04637/14
A28: ='CONN-COSC-R-14-SEC-2'!A25 -> 17 | B28: ='CONN-COSC-R-14-SEC-2'!B25 -> SAMUEL | C28: ='CONN-COSC-R-14-SEC-2'!C25 -> SILESHI | D28: ='CONN-COSC-R-14-SEC-2'!E25 -> 04561/14 | I28: =D28 -> 04561/14
A29: ='CONN-COSC-R-14-SEC-2'!A26 -> 18 | B29: ='CONN-COSC-R-14-SEC-2'!B26 -> SEBAIF | C29: ='CONN-COSC-R-14-SEC-2'!C26 -> MOHAMMED | D29: ='CONN-COSC-R-14-SEC-2'!E26 -> 04550/14 | I29: =D29 -> 04550/14
A30: ='CONN-COSC-R-14-SEC-2'!A27 -> 19 | B30: ='CONN-COSC-R-14-SEC-2'!B27 -> TESFALEM | C30: ='CONN-COSC-R-14-SEC-2'!C27 -> BERHE | D30: ='CONN-COSC-R-14-SEC-2'!E27 -> 04535/14 | I30: =D30 -> 04535/14
A31: ='CONN-COSC-R-14-SEC-2'!A28 -> 20 | B31: ='CONN-COSC-R-14-SEC-2'!B28 -> TIZITA | C31: ='CONN-COSC-R-14-SEC-2'!C28 -> TESFAYE | D31: ='CONN-COSC-R-14-SEC-2'!E28 -> 04569/14 | I31: =D31 -> 04569/14
A32: ='CONN-COSC-R-14-SEC-2'!A29 -> 21 | B32: ='CONN-COSC-R-14-SEC-2'!B29 -> TSION | C32: ='CONN-COSC-R-14-SEC-2'!C29 -> MULUGETA | D32: ='CONN-COSC-R-14-SEC-2'!E29 -> 04571/14 | I32: =D32 -> 04571/14
A33: ='CONN-COSC-R-14-SEC-2'!A30 -> 22 | B33: ='CONN-COSC-R-14-SEC-2'!B30 -> WALBEK | C33: ='CONN-COSC-R-14-SEC-2'!C30 -> HUSSEN | D33: ='CONN-COSC-R-14-SEC-2'!E30 -> 04738/14 | I33: =D33 -> 04738/14
A34: ='CONN-COSC-R-14-SEC-2'!A31 -> 23 | B34: ='CONN-COSC-R-14-SEC-2'!B31 -> XENOS | C34: ='CONN-COSC-R-14-SEC-2'!C31 -> WOGAYEHU | D34: ='CONN-COSC-R-14-SEC-2'!E31 -> 04557/14 | I34: =D34 -> 04557/14
A35: ='CONN-COSC-R-14-SEC-2'!A32 -> 24 | B35: ='CONN-COSC-R-14-SEC-2'!B32 -> YAHYA | C35: ='CONN-COSC-R-14-SEC-2'!C32 -> IBRAHIM | D35: ='CONN-COSC-R-14-SEC-2'!E32 -> 04572/14 | I35: =D35 -> 04572/14
A36: ='CONN-COSC-R-14-SEC-2'!A33 -> 25 | B36: ='CONN-COSC-R-14-SEC-2'!B33 -> YASET | C36: ='CONN-COSC-R-14-SEC-2'!C33 -> TIRUSEW | D36: ='CONN-COSC-R-14-SEC-2'!E33 -> 06049/14 | I36: =D36 -> 06049/14
A37: ='CONN-COSC-R-14-SEC-2'!A34 -> 26 | B37: ='CONN-COSC-R-14-SEC-2'!B34 -> YESUNEH | C37: ='CONN-COSC-R-14-SEC-2'!C34 -> MOGES | D37: ='CONN-COSC-R-14-SEC-2'!E34 -> 04558/14 | I37: =D37 -> 04558/14
... A41: ='CONN-COSC-R-14-SEC-2'!A38 -> 30 | B41: ='CONN-COSC-R-14-SEC-2'!B38 -> ZELALEM | C41: ='CONN-COSC-R-14-SEC-2'!C38 -> MULUNEH | D41: ='CONN-COSC-R-14-SEC-2'!E38 -> 04559/14 | I41: =D41 -> 04559/14
I42: ADD STUDENTS
A43: 1 | B43: ='CONN-COSC-R-14-SEC-2'!B42 -> DEME | C43: ='CONN-COSC-R-14-SEC-2'!C42 -> TEMESGEN | D43: ='CONN-COSC-R-14-SEC-2'!E42 -> 02588/12 | I43: =D43 -> 02588/12
...

Sheet Sheet2

Sheet ATT-COSC-07
D1: UNITY UNIVERSITY ADAMA SPECIAL CAMPUS
D2: COSC/07 first SEM 2017 Cont.ASSESSMENTFORM
B4: COURSE TITLE:Multimedia System | G4: COSC467 | J4: sec. 1
A5: NO. | B5: NAME | C5: SEX | D5: ID.NO | E5: Monthly Test | H5: ASSIGNMENT | J5: Attend | K5: Total | L5: Final | M5: Total | N5: Grade
E6: 0.1 | F6: 0.1 | G6: 0.1 | H6: Ind(10%) | I6: Team(5%) | J6: 0.05 | K6: 0.5 | L6: 0.5 | M6: 1
A7: 1 | B7: ABDULMELIK ABDULAZIZ | D7: 44977/07
A8: 2 | B8: ABEBE DURE | D8: 44985/09
A9: 3 | B9: ABRHAM CHEKOL | D9: 44791/07
A10: 4 | B10: ABUBEKER KEMAL | D10: 44945/07
A11: 5 | B11: ASMEROM W/HWARIYAT | D11: 44797/07
A12: 6 | B12: BESUKAL DEMISEW | D12: 44814/07
A13: 7 | B13: BEYENE DABI | D13: 44799/07
A14: 8 | B14: DIBORA DANIEL | D14: 45162/07
A15: 9 | B15: ENDRIAS TIBEBU | D15: 44932/07
A16: 10 | B16: GEMECHU PETROS | D16: 44924/07
A17: 11 | B17: HAILELUEL ENDALE | D17: 44949/07
A18: 12 | B18: HIYAW HUSSEN | D18: 44789/07
... A23: 17 | B23: MAHLET KADIR | D23: 44795/07
A24: 18 | B24: ORION ZERFU
A25: 19 | B25: SINEWORK GIRMA | D25: 44790/07
A26: 20 | B26: TINSAE TADESSE | D26: 44798/07
A27: 21 | B27: YOHANNES AFEWORK | D27: 44872/07
A28: 22
D29: ADD STUDENTS
A30: 1

Sheet COSC-R-07
D1: UNITY UNIVERSITY ADAMA SPECIAL CAMPUS
D2: COSC/07 first SEM 2017 Cont.ASSESSMENTFORM
B4: COURSE TITLE:Multimedia System | G4: COSC467 | J4: sec. 1
A5: NO. | B5: NAME | C5: SEX | D5: ID.NO | E5: Monthly Test | H5: ASSIGNMENT | J5: Attend | K5: Total | L5: Final | M5: Total | N5: Grade
E6: 0.1 | F6: 0.1 | G6: 0.1 | H6: Ind(10%) | I6: Team(5%) | J6: 0.05 | K6: 0.5 | L6: 0.5 | M6: 1
A7: 1 | B7: ABDULMELIK ABDULAZIZ | D7: 44977/07
A8: 2 | B8: ABEBE DURE | D8: 44985/07
A9: 3 | B9: ABRHAM CHEKOL | D9: 44791/07
A10: 4 | B10: ABUBEKER KEMAL | D10: 44945/07
A11: 5 | B11: ASMEROM W/HWARIYAT | D11: 44797/07
A12: 6 | B12: BESUKAL DEMISEW | D12: 44814/07
A13: 7 | B13: BEYENE DABI | D13: 44799/07
A14: 8 | B14: DIBORA DANIEL | D14: 45162/07
A15: 9 | B15: ENDRIAS TIBEBU | D15: 44932/07
A16: 10 | B16: GEMECHU PETROS | D16: 44924/07
A17: 11 | B17: HAILELUEL ENDALE | D17: 44929/07
A18: 12 | B18: HIYAW HUSSEN | D18: 44789/07
... A27: 21 | B27: YOHANNES AFEWORK | D27: 44872/07
A28: 22
D29: ADD STUDENTS
A30: 1
D33: UNITY UNIVERSITY ADAMA SPECIAL CAMPUS
D34: COSC/07 first SEM 2017 Cont.ASSESSMENTFORM
B36: COURSE TITLE:E-commerce | G36: COSC431 | J36: sec. 1
A37: NO. | B37: NAME | C37: SEX | D37: ID.NO | E37: Monthly Test | H37: ASSIGNMENT | J37: Attend | K37: Total | L37: Final | M37: Total | N37: Grade
E38: 0.1 | F38: 0.1 | G38: 0.1 | H38: Ind(10%) | I38: Team(5%) | J38: 0.05 | K38: 0.5 | L38: 0.5 | M38: 1
A60: 22
D61: ADD STUDENTS
A62: 1
D65: UNITY UNIVERSITY ADAMA SPECIAL CAMPUS
D66: COSC/07 first SEM 2017 Cont.ASSESSMENTFORM
B68: COURSE TITLE:FINAL PROJECT I | G68: COSC372 | J68: sec. 1
A69: NO. | B69: NAME | C69: SEX | D69: ID.NO | E69: Monthly Test | H69: ASSIGNMENT | J69: Attend | K69: Total | L69: Final | M69: Total | N69: Grade
E70: 0.1 | F70: 0.1 | G70: 0.1 | H70: Ind(10%) | I70: Team(5%) | J70: 0.05 | K70: 0.5 | L70: 0.5 | M70: 1
A71: 1 | B71: ABDULMELIK ABDULAZIZ | D71: 44977/07
A72: 2 | B72: ABEBE DURE | D72: 44985/07
A73: 3 | B73: ABRHAM CHEKOL | D73: 44791/07
A74: 4 | B74: ABUBEKER KEMAL | D74: 44945/07
A75: 5 | B75: ASMEROM W/HWARIYAT | D75: 44797/07
A76: 6 | B76: BESUKAL DEMISEW | D76: 44814/07
...

Sheet GRS-COSC-07
B1: UNITY UNIVERSITY
B2: ADAMA SPECIAL CAMPUS
B3: OFFICE OF REGISTRAR
B4: GRADE SUBMISION FORM
B5: YEAR III SEM I/2017 | G5: YEAR III SEM I/2017
B6: COURSE TITLE:Multimedia System | G6: COURSE TITLE:
G7: Multimedia System
B8: COURSENO.COSC467 | G8: COURSE NO.COSC467
B9: SECTION:COSC/R/07 | G9: SECTION:COSC/R/07
A10: S.N | B10: STUDENTS NAME | C10: ID.NO | D10: GRADE | H10: ID.NO | I10: GRADE
A11: 1 | B11: ABDULMELIK ABDULAZIZ | C11: 44977/07 | H11: =C11 -> 44977/07
A12: 2 | B12: ABEBE DURE | C12: 44985/07 | E12: Grade Summary | H12: =C12 -> 44985/07
A13: 3 | B13: ABRHAM CHEKOL | C13: 44791/07 | E13: A+'S------ | H13: =C13 -> 44791/07
A14: 4 | B14: ABUBEKER KEMAL | C14: 44945/07 | E14: A'S | H14: =C14 -> 44945/07
A15: 5 | B15: ASMEROM W/HWARIYAT | C15: 44797/07 | E15: B+'S----- | H15: =C15 -> 44797/07
A16: 6 | B16: BESUKAL DEMISEW | C16: 44814/07 | E16: B'S------- | H16: =C16 -> 44814/07
A17: 7 | B17: BEYENE DABI | C17: 44799/07 | E17: C+'S----- | H17: =C17 -> 44799/07
A18: 8 | B18: DIBORA DANIEL | C18: 45162/07 | E18: C'S------ | H18: =C18 -> 45162/07
A19: 9 | B19: ENDRIAS TIBEBU | C19: 44932/07 | E19: D'S------ | H19: =C19 -> 44932/07
A20: 10 | B20: GEMECHU PETROS | C20: 44924/07 | E20: NG'S----- | H20: =C20 -> 44924/07
A21: 11 | B21: HAILELUEL ENDALE | C21: 44929/07 | E21: I'S-------- | H21: =C21 -> 44929/07
A22: 12 | B22: HIYAW HUSSEN | C22: 44789/07 | E22: TOT----- | H22: =C22 -> 44789/07
A23: 13 | B23: KALEAB DEJENE | C23: 44928/07 | H23: =C23 -> 44928/07
A24: 14 | B24: KALKIDAN TESHOME | C24: 45179/07 | H24: =C24 -> 45179/07
A25: 15 | B25: KASSAHUN HUNDE | C25: 44829/07 | H25: =C25 -> 44829/07
A26: 16 | B26: LEYILA NURI | C26: 45557/07 | H26: =C26 -> 45557/07
A27: 17 | B27: MAHLET KADIR | C27: 44795/07 | H27: =C27 -> 44795/07
A28: 18 | B28: ORION ZERFU | C28: 44795/07 | H28: =C28 -> 44795/07
A29: 19 | B29: SINEWORK GIRMA | C29: 44790/07 | H29: =C29 -> 44790/07
A30: 20 | B30: TINSAE TADESSE | C30: 44798/07 | H30: =C30 -> 44798/07
A31: 21 | B31: YOHANNES AFEWORK | C31: 44872/07 | H31: =C31 -> 44872/07
B32: ADD STUDENTS | H32: ADD STUDENTS
B33: INST.NAME__________________ | C33: SIGNATURE________________ | E33: ____________
B34: DATE-____________________
B36: DEP.HEAD NAME______________ | C36: SIGNATUE___________________
B37: DATE:___________________
B41: UNITY UNIVERSITY
B42: ADAMA SPECIAL CAMPUS
B43: OFFICE OF REGISTRAR
B44: GRADE SUBMISION FORM
...

Sheet ATT-COSC-R-14-3
A1: COSC/REG/14
A2: UNITY UNIVERSITY ADAMA CAMPUS
A3: COSC/R/14 Year II Semester II 2023 (2015 E.C) ATTENDANCE FORM
A5: COURSE TITLE: Basic Electricity & Electronics COURSE NO: Phys 2042 SEC-3 INSTRUCTOR:
A6: NO. | B6: STUDENTS NAME | E6: ID.NO
A7: 1 | B7: ABDI | C7: FEYISA | D7: LEGESE | E7: 04597/14
A8: 2 | B8: ABDUREHIM | C8: AHMED | D8: ROBA | E8: 04599/14
A9: 3 | B9: ABDUREHMAN | C9: MUZE | D9: SHIFERAW | E9: 04584/14
A10: 4 | B10: ABENET | C10: BIRHANU | D10: SENBU | E10: 04590/14
A11: 5 | B11: ABENEZER | C11: AYELE | D11: KIFLE | E11: 04605/14
A12: 6 | B12: AMANUEL | C12: ATNAFU | D12: ANSA | E12: 04633/14
A13: 7 | B13: AYALKBET | C13: SHIFERAW | D13: KETEMA | E13: 04627/14
A14: 8 | B14: BEDO | C14: TELILA | D14: BOSET | E14: 04587/14
A15: 9 | B15: BINIYAM | C15: ALEMAYEHU | D15: TESFAYE | E15: 04586/14
A16: 10 | B16: DAGMAWI | C16: TEFERI | D16: GETANEH | E16: 04606/14
A17: 11 | B17: ENDALE | C17: ASEGED | D17: BIRU | E17: 04593/14
A18: 12 | B18: FEVEN | C18: FIKADU | D18: GETAHUN | E18: 04629/14
... A41: 35 | B41: YOSEF | C41: KASSU | D41: GOMERA | E41: 04387/14
A42: 36
A43: 37
A44: ADD STUDENTS
A45: NO. | B45: STUDENTS NAME | E45: ID.NO
A46: 1
A47: 2
A48: 3
A49: 4
A50: 5
A51: UNITY UNIVERSITY ADAMA CAMPUS
A52: COSC/R/14 Year II Semester II 2023 (2015 E.C) ATTENDANCE FORM
A54: COURSE TITLE: Linear Algebra COURSE NO: Math 2022 SEC-3 INSTRUCTOR:
A55: NO. | B55: STUDENTS NAME | E55: ID.NO
A56: 1 | B56: ABDI | C56: FEYISA | D56: LEGESE | E56: 04597/14
A57: 2 | B57: ABDUREHIM | C57: AHMED | D57: ROBA | E57: 04599/14
A58: 3 | B58: ABDUREHMAN | C58: MUZE | D58: SHIFERAW | E58: 04584/14
A59: 4 | B59: ABENET | C59: BIRHANU | D59: SENBU | E59: 04590/14
A60: 5 | B60: ABENEZER | C60: AYELE | D60: KIFLE | E60: 04605/14
A61: 6 | B61: AMANUEL | C61: ATNAFU | D61: ANSA | E61: 04633/14
A62: 7 | B62: AYALKBET | C62: SHIFERAW | D62: KETEMA | E62: 04627/14
A63: 8 | B63: BEDO | C63: TELILA | D63: BOSET | E63: 04587/14
A64: 9 | B64: BINIYAM | C64: ALEMAYEHU | D64: TESFAYE | E64: 04586/14
...

Sheet CONN-BUAD-MRKT-3
A1: COSC/REG/14
A56: COSC/R/14 Year II Semester II 2023 (2015 E.C) Cont.ASSESSMENT FORM
A58: ='ATT-COSC-R-14-3'!A54 -> COURSE TITLE: Linear Algebra COURSE NO: Math 2022 SEC-3 INSTRUCTOR: | J58: Sisay K.
A59: NO. | B59: NAME | E59: ID.NO | H59: ASSIGNMENT | J59: Attend | K59: Total | L59: Final | M59: Total | N59: Grade
F60: 0.05 | G60: 0.15 | H60: Ind.(10%) | I60: Team(15%) | J60: 0.05 | K60: 0.5 | L60: 0.5 | M60: 1
A61: ='ATT-COSC-R-14-3'!A56 -> 1 | E61: ='ATT-COSC-R-14-3'!E56 -> 04597/14 | F61: 5 | H61: 10 | I61: 14 | J61: 4 | K61: 24 | L61: 7.5 | M61: 31.5
A62: ='ATT-COSC-R-14-3'!A57 -> 2 | E62: ='ATT-COSC-R-14-3'!E57 -> 04599/14 | F62: 5 | G62: 5 | H62: 8 | J62: 4 | K62: =SUM(F62:J62) -> 22 | L62: 7.5 | M62: =SUM(K62:L62) -> 29.5
A63: ='ATT-COSC-R-14-3'!A58 -> 3 | E63: ='ATT-COSC-R-14-3'!E58 -> 04584/14 | F63: 5 | G63: 8 | H63: 6 | I63: 13.5 | J63: 5 | K63: 27.5 | L63: 12.5 | M63: 40
A64: ='ATT-COSC-R-14-3'!A59 -> 4 | E64: ='ATT-COSC-R-14-3'!E59 -> 04590/14 | F64: 5 | G64: 4 | H64: 8 | I64: 14 | J64: 3 | K64: 26 | L64: 12.5 | M64: 38.5
A65: ='ATT-COSC-R-14-3'!A60 -> 5 | E65: ='ATT-COSC-R-14-3'!E60 -> 04605/14 | F65: 5 | H65: 8 | I65: 15 | J65: 5 | K65: 23 | L65: 18 | M65: 41
A66: ='ATT-COSC-R-14-3'!A61 -> 6 | E66: ='ATT-COSC-R-14-3'!E61 -> 04633/14 | F66: 0 | G66: 3 | H66: 0 | I66: 14 | J66: 4 | K66: 17 | L66: 12.5 | M66: 29.5
A67: ='ATT-COSC-R-14-3'!A62 -> 7 | E67: ='ATT-COSC-R-14-3'!E62 -> 04627/14 | F67: 5 | G67: 9 | H67: 8 | I67: 13.5 | J67: 4 | K67: 30.5 | L67: 23 | M67: 53.5
A68: ='ATT-COSC-R-14-3'!A63 -> 8 | E68: ='ATT-COSC-R-14-3'!E63 -> 04587/14 | F68: 0 | H68: 0 | I68: 14 | J68: 2 | K68: 14 | L68: 5 | M68: 19
A69: ='ATT-COSC-R-14-3'!A64 -> 9 | E69: ='ATT-COSC-R-14-3'!E64 -> 04586/14 | F69: 5 | G69: 5 | H69: 9 | I69: 13.5 | J69: 5 | K69: 27.5 | L69: 15 | M69: 42.5
A70: ='ATT-COSC-R-14-3'!A65 -> 10 | E70: ='ATT-COSC-R-14-3'!E65 -> 04606/14 | F70: 0 | G70: 16.5 | H70: 9 | I70: 15 | J70: 5 | K70: 40.5 | L70: 40 | M70: 80.5
A71: ='ATT-COSC-R-14-3'!A66 -> 11 | E71: ='ATT-COSC-R-14-3'!E66 -> 04593/14 | F71: 0 | G71: 4 | H71: 9 | J71: 4 | K71: 13 | L71: 5 | M71: 18
A72: ='ATT-COSC-R-14-3'!A67 -> 12 | E72: ='ATT-COSC-R-14-3'!E67 -> 04629/14 | F72: 0 | G72: 13 | H72: 9.5 | J72: 5 | K72: 22.5 | M72: 22.5 | N72: I
A73: ='ATT-COSC-R-14-3'!A68 -> 13 | E73: ='ATT-COSC-R-14-3'!E68 -> 04589/14 | F73: 0 | G73: 8 | H73: 9 | I73: 14 | J73: 5 | K73: 31 | L73: 7.5 | M73: 38.5
A74: ='ATT-COSC-R-14-3'!A69 -> 14 | E74: ='ATT-COSC-R-14-3'!E69 -> 04595/14 | F74: 5 | G74: 8 | H74: 10 | I74: 15 | J74: 5 | K74: 33 | L74: 19.5 | M74: 52.5
A75: ='ATT-COSC-R-14-3'!A70 -> 15 | E75: ='ATT-COSC-R-14-3'!E70 -> 04581/14 | F75: 5 | G75: 3 | H75: 8 | I75: 15 | J75: 5 | K75: 26 | L75: 6 | M75: 32
A76: ='ATT-COSC-R-14-3'!A71 -> 16 | E76: ='ATT-COSC-R-14-3'!E71 -> 04583/14 | F76: 0 | G76: 9 | H76: 9 | I76: 15 | J76: 5 | K76: 33 | L76: 24 | M76: 57
A77: ='ATT-COSC-R-14-3'!A72 -> 17 | E77: ='ATT-COSC-R-14-3'!E72 -> 04534/14 | F77: 0 | G77: 7 | H77: 9 | I77: 14 | J77: 4 | K77: 30 | L77: 10 | M77: 40
A78: ='ATT-COSC-R-14-3'!A73 -> 18 | E78: ='ATT-COSC-R-14-3'!E73 -> 04626/14 | F78: 0 | G78: 5 | H78: 8 | I78: 13.5 | J78: 3 | K78: 26.5 | L78: 7.5 | M78: 34
A79: ='ATT-COSC-R-14-3'!A74 -> 19 | E79: ='ATT-COSC-R-14-3'!E74 -> 04608/14 | F79: 5 | G79: 5.5 | H79: 9 | I79: 13 | J79: 5 | K79: 27.5 | L79: 10.5 | M79: 38
A80: ='ATT-COSC-R-14-3'!A75 -> 20 | E80: ='ATT-COSC-R-14-3'!E75 -> 04612/14 | F80: 5 | G80: 13 | H80: 10 | I80: 14 | J80: 4 | K80: 37 | L80: 10 | M80: 47
A81: ='ATT-COSC-R-14-3'!A76 -> 21 | E81: ='ATT-COSC-R-14-3'!E76 -> 04625/14 | F81: 5 | G81: 19.5 | H81: 10 | I81: 15 | J81: 5 | K81: 44.5 | L81: 45 | M81: 89.5
A82: ='ATT-COSC-R-14-3'!A77 -> 22 | E82: ='ATT-COSC-R-14-3'!E77 -> 04603/14 | F82: 0 | G82: 5 | H82: 9 | I82: 13.5 | J82: 5 | K82: 27.5 | L82: 10 | M82: 37.5
A83: ='ATT-COSC-R-14-3'!A78 -> 23 | E83: ='ATT-COSC-R-14-3'!E78 -> 05107/14 | F83: 5 | G83: 3 | H83: 9 | I83: 13 | J83: 5 | K83: 25 | L83: 10 | M83: 35
A84: ='ATT-COSC-R-14-3'!A79 -> 24 | E84: ='ATT-COSC-R-14-3'!E79 -> 04594/14 | F84: 0 | G84: 8 | H84: 9 | I84: 13.5 | J84: 5 | K84: 30.5 | L84: 19.5 | M84: 50
... A94: ='ATT-COSC-R-14-3'!A89 -> 34 | E94: ='ATT-COSC-R-14-3'!E89 -> 04623/14 | F94: 5 | G94: 9 | H94: 9.5 | I94: 13.5 | J94: 5 | K94: 32 | L94: 15.5 | M94: 47.5
A95: ='ATT-COSC-R-14-3'!A90 -> 35 | E95: ='ATT-COSC-R-14-3'!E90 -> 04387/14 | F95: 5 | G95: 9 | H95: 9 | I95: 13 | J95: 5 | K95: 31 | M95: 31 | N95: I
A96: ='ATT-COSC-R-14-3'!A91 -> 36 | E96: ='ATT-COSC-R-14-3'!E91 -> 0
A97: ='ATT-COSC-R-14-3'!A92 -> 37 | E97: ='ATT-COSC-R-14-3'!E92 -> 0
A98: ='ATT-COSC-R-14-3'!A93 -> 38 | E98: ='ATT-COSC-R-14-3'!E93 -> 0
A99: ='ATT-COSC-R-14-3'!A94 -> 39 | E99: ='ATT-COSC-R-14-3'!E94 -> 0
A100: ='ATT-COSC-R-14-3'!A95 -> 40 | E100: ='ATT-COSC-R-14-3'!E95 -> 0
